2024-07-03 14:25:51,994 | INFO | django.utils.autoreload | Watching for file changes with StatReloader
2024-07-03 14:25:52,486 | INFO | root | Products for shop index [('laptop', 500), ('desktop', 700), ('mouse', 50), ('keyboard', 70), ('smartphone', 150)]
2024-07-03 14:25:52,635 | INFO | root | Products for shop index [('laptop', 500), ('desktop', 700), ('mouse', 50), ('keyboard', 70), ('smartphone', 150)]
2024-07-03 14:25:52,812 | INFO | root | Products for shop index [('laptop', 500), ('desktop', 700), ('mouse', 50), ('keyboard', 70), ('smartphone', 150)]
2024-07-03 14:25:52,975 | INFO | root | Products for shop index [('laptop', 500), ('desktop', 700), ('mouse', 50), ('keyboard', 70), ('smartphone', 150)]
2024-07-03 14:25:53,139 | INFO | root | Products for shop index [('laptop', 500), ('desktop', 700), ('mouse', 50), ('keyboard', 70), ('smartphone', 150)]
2024-07-03 14:25:53,297 | INFO | root | Products for shop index [('laptop', 500), ('desktop', 700), ('mouse', 50), ('keyboard', 70), ('smartphone', 150)]
2024-07-03 14:25:53,497 | INFO | root | Products for shop index [('laptop', 500), ('desktop', 700), ('mouse', 50), ('keyboard', 70), ('smartphone', 150)]
2024-07-03 18:54:24,956 | INFO | django.utils.autoreload | /Users/moskvinangarkhaev/PycharmProjects/python_django/mysite/shopapp/views.py changed, reloading.
2024-07-03 19:01:18,344 | INFO | django.utils.autoreload | Watching for file changes with StatReloader
2024-07-04 14:02:23,799 | INFO | django.utils.autoreload | Watching for file changes with StatReloader
2024-07-04 14:30:31,673 | INFO | django.utils.autoreload | Watching for file changes with StatReloader
2024-07-04 14:30:40,759 | INFO | django.utils.autoreload | Watching for file changes with StatReloader
2024-07-04 14:30:42,732 | WARNING | django.request | Not Found: /
2024-07-04 14:30:42,821 | WARNING | django.request | Not Found: /favicon.ico
2024-07-04 18:03:39,017 | INFO | django.utils.autoreload | Watching for file changes with StatReloader
2024-07-04 18:03:41,198 | WARNING | django.request | Not Found: /
2024-07-04 18:03:48,816 | WARNING | django.request | Not Found: /products
2024-07-04 18:04:05,221 | WARNING | django.request | Not Found: /ru/shop/orders/export
2024-07-04 18:04:29,128 | WARNING | django.request | Not Found: /shop/orders/export
2024-07-04 18:04:47,928 | ERROR | django.request | Internal Server Error: /ru/shop/order/export
Traceback (most recent call last):
  File "/Users/moskvinangarkhaev/PycharmProjects/python_django/venv/lib/python3.11/site-packages/django/core/handlers/exception.py", line 55, in inner
    response = get_response(request)
               ^^^^^^^^^^^^^^^^^^^^^
  File "/Users/moskvinangarkhaev/PycharmProjects/python_django/venv/lib/python3.11/site-packages/django/core/handlers/base.py", line 197, in _get_response
    response = wrapped_callback(request, *callback_args, **callback_kwargs)
               ^^^^^^^^^^^^^^^^^^^^^^^^^^^^^^^^^^^^^^^^^^^^^^^^^^^^^^^^^^^^
  File "/Users/moskvinangarkhaev/PycharmProjects/python_django/venv/lib/python3.11/site-packages/sentry_sdk/integrations/django/views.py", line 90, in sentry_wrapped_callback
    return callback(request, *args, **kwargs)
           ^^^^^^^^^^^^^^^^^^^^^^^^^^^^^^^^^^
  File "/Users/moskvinangarkhaev/PycharmProjects/python_django/venv/lib/python3.11/site-packages/django/views/generic/base.py", line 104, in view
    return self.dispatch(request, *args, **kwargs)
           ^^^^^^^^^^^^^^^^^^^^^^^^^^^^^^^^^^^^^^^
  File "/Users/moskvinangarkhaev/PycharmProjects/python_django/venv/lib/python3.11/site-packages/django/contrib/auth/mixins.py", line 135, in dispatch
    return super().dispatch(request, *args, **kwargs)
           ^^^^^^^^^^^^^^^^^^^^^^^^^^^^^^^^^^^^^^^^^^
  File "/Users/moskvinangarkhaev/PycharmProjects/python_django/venv/lib/python3.11/site-packages/django/views/generic/base.py", line 143, in dispatch
    return handler(request, *args, **kwargs)
           ^^^^^^^^^^^^^^^^^^^^^^^^^^^^^^^^^
  File "/Users/moskvinangarkhaev/PycharmProjects/python_django/mysite/shopapp/views.py", line 229, in get
    1/0
    ~^~
ZeroDivisionError: division by zero
2024-07-04 18:12:36,140 | INFO | django.utils.autoreload | /Users/moskvinangarkhaev/PycharmProjects/python_django/mysite/shopapp/views.py changed, reloading.
2024-07-04 18:12:36,756 | INFO | django.utils.autoreload | Watching for file changes with StatReloader
2024-07-08 12:28:25,946 | INFO | django.utils.autoreload | Watching for file changes with StatReloader
2024-07-08 12:28:28,081 | WARNING | django.request | Not Found: /
2024-07-08 12:28:37,561 | WARNING | django.request | Not Found: /blogapp/
2024-07-08 12:31:34,967 | INFO | django.utils.autoreload | /Users/moskvinangarkhaev/PycharmProjects/python_django/mysite/blogapp/views.py changed, reloading.
2024-07-08 12:31:35,445 | INFO | django.utils.autoreload | Watching for file changes with StatReloader
2024-07-08 12:39:49,397 | INFO | django.utils.autoreload | /Users/moskvinangarkhaev/PycharmProjects/python_django/mysite/blogapp/urls.py changed, reloading.
2024-07-08 12:39:49,811 | INFO | django.utils.autoreload | Watching for file changes with StatReloader
2024-07-08 12:43:25,517 | INFO | django.utils.autoreload | /Users/moskvinangarkhaev/PycharmProjects/python_django/mysite/blogapp/views.py changed, reloading.
2024-07-08 12:43:26,033 | INFO | django.utils.autoreload | Watching for file changes with StatReloader
2024-07-08 12:46:43,940 | INFO | django.utils.autoreload | Watching for file changes with StatReloader
2024-07-08 12:47:15,502 | ERROR | django.request | Internal Server Error: /blogapp/article/4
Traceback (most recent call last):
  File "/Users/moskvinangarkhaev/PycharmProjects/python_django/venv/lib/python3.11/site-packages/django/core/handlers/exception.py", line 55, in inner
    response = get_response(request)
               ^^^^^^^^^^^^^^^^^^^^^
  File "/Users/moskvinangarkhaev/PycharmProjects/python_django/venv/lib/python3.11/site-packages/django/core/handlers/base.py", line 220, in _get_response
    response = response.render()
               ^^^^^^^^^^^^^^^^^
  File "/Users/moskvinangarkhaev/PycharmProjects/python_django/venv/lib/python3.11/site-packages/sentry_sdk/integrations/django/views.py", line 41, in sentry_patched_render
    return old_render(self)
           ^^^^^^^^^^^^^^^^
  File "/Users/moskvinangarkhaev/PycharmProjects/python_django/venv/lib/python3.11/site-packages/django/template/response.py", line 114, in render
    self.content = self.rendered_content
                   ^^^^^^^^^^^^^^^^^^^^^
  File "/Users/moskvinangarkhaev/PycharmProjects/python_django/venv/lib/python3.11/site-packages/sentry_sdk/utils.py", line 1713, in runner
    return sentry_patched_function(*args, **kwargs)
           ^^^^^^^^^^^^^^^^^^^^^^^^^^^^^^^^^^^^^^^^
  File "/Users/moskvinangarkhaev/PycharmProjects/python_django/venv/lib/python3.11/site-packages/sentry_sdk/integrations/django/templates.py", line 77, in rendered_content
    return real_rendered_content.fget(self)
           ^^^^^^^^^^^^^^^^^^^^^^^^^^^^^^^^
  File "/Users/moskvinangarkhaev/PycharmProjects/python_django/venv/lib/python3.11/site-packages/django/template/response.py", line 92, in rendered_content
    return template.render(context, self._request)
           ^^^^^^^^^^^^^^^^^^^^^^^^^^^^^^^^^^^^^^^
  File "/Users/moskvinangarkhaev/PycharmProjects/python_django/venv/lib/python3.11/site-packages/django/template/backends/django.py", line 61, in render
    return self.template.render(context)
           ^^^^^^^^^^^^^^^^^^^^^^^^^^^^^
  File "/Users/moskvinangarkhaev/PycharmProjects/python_django/venv/lib/python3.11/site-packages/django/template/base.py", line 171, in render
    return self._render(context)
           ^^^^^^^^^^^^^^^^^^^^^
  File "/Users/moskvinangarkhaev/PycharmProjects/python_django/venv/lib/python3.11/site-packages/django/test/utils.py", line 111, in instrumented_test_render
    return self.nodelist.render(context)
           ^^^^^^^^^^^^^^^^^^^^^^^^^^^^^
  File "/Users/moskvinangarkhaev/PycharmProjects/python_django/venv/lib/python3.11/site-packages/django/template/base.py", line 1000, in render
    return SafeString("".join([node.render_annotated(context) for node in self]))
                              ^^^^^^^^^^^^^^^^^^^^^^^^^^^^^^^^^^^^^^^^^^^^^^^^^
  File "/Users/moskvinangarkhaev/PycharmProjects/python_django/venv/lib/python3.11/site-packages/django/template/base.py", line 1000, in <listcomp>
    return SafeString("".join([node.render_annotated(context) for node in self]))
                               ^^^^^^^^^^^^^^^^^^^^^^^^^^^^^^
  File "/Users/moskvinangarkhaev/PycharmProjects/python_django/venv/lib/python3.11/site-packages/django/template/base.py", line 961, in render_annotated
    return self.render(context)
           ^^^^^^^^^^^^^^^^^^^^
  File "/Users/moskvinangarkhaev/PycharmProjects/python_django/venv/lib/python3.11/site-packages/django/template/loader_tags.py", line 159, in render
    return compiled_parent._render(context)
           ^^^^^^^^^^^^^^^^^^^^^^^^^^^^^^^^
  File "/Users/moskvinangarkhaev/PycharmProjects/python_django/venv/lib/python3.11/site-packages/django/test/utils.py", line 111, in instrumented_test_render
    return self.nodelist.render(context)
           ^^^^^^^^^^^^^^^^^^^^^^^^^^^^^
  File "/Users/moskvinangarkhaev/PycharmProjects/python_django/venv/lib/python3.11/site-packages/django/template/base.py", line 1000, in render
    return SafeString("".join([node.render_annotated(context) for node in self]))
                              ^^^^^^^^^^^^^^^^^^^^^^^^^^^^^^^^^^^^^^^^^^^^^^^^^
  File "/Users/moskvinangarkhaev/PycharmProjects/python_django/venv/lib/python3.11/site-packages/django/template/base.py", line 1000, in <listcomp>
    return SafeString("".join([node.render_annotated(context) for node in self]))
                               ^^^^^^^^^^^^^^^^^^^^^^^^^^^^^^
  File "/Users/moskvinangarkhaev/PycharmProjects/python_django/venv/lib/python3.11/site-packages/django/template/base.py", line 961, in render_annotated
    return self.render(context)
           ^^^^^^^^^^^^^^^^^^^^
  File "/Users/moskvinangarkhaev/PycharmProjects/python_django/venv/lib/python3.11/site-packages/django/template/loader_tags.py", line 65, in render
    result = block.nodelist.render(context)
             ^^^^^^^^^^^^^^^^^^^^^^^^^^^^^^
  File "/Users/moskvinangarkhaev/PycharmProjects/python_django/venv/lib/python3.11/site-packages/django/template/base.py", line 1000, in render
    return SafeString("".join([node.render_annotated(context) for node in self]))
                              ^^^^^^^^^^^^^^^^^^^^^^^^^^^^^^^^^^^^^^^^^^^^^^^^^
  File "/Users/moskvinangarkhaev/PycharmProjects/python_django/venv/lib/python3.11/site-packages/django/template/base.py", line 1000, in <listcomp>
    return SafeString("".join([node.render_annotated(context) for node in self]))
                               ^^^^^^^^^^^^^^^^^^^^^^^^^^^^^^
  File "/Users/moskvinangarkhaev/PycharmProjects/python_django/venv/lib/python3.11/site-packages/django/template/base.py", line 961, in render_annotated
    return self.render(context)
           ^^^^^^^^^^^^^^^^^^^^
  File "/Users/moskvinangarkhaev/PycharmProjects/python_django/venv/lib/python3.11/site-packages/django/template/defaulttags.py", line 479, in render
    url = reverse(view_name, args=args, kwargs=kwargs, current_app=current_app)
          ^^^^^^^^^^^^^^^^^^^^^^^^^^^^^^^^^^^^^^^^^^^^^^^^^^^^^^^^^^^^^^^^^^^^^
  File "/Users/moskvinangarkhaev/PycharmProjects/python_django/venv/lib/python3.11/site-packages/django/urls/base.py", line 88, in reverse
    return resolver._reverse_with_prefix(view, prefix, *args, **kwargs)
           ^^^^^^^^^^^^^^^^^^^^^^^^^^^^^^^^^^^^^^^^^^^^^^^^^^^^^^^^^^^^
  File "/Users/moskvinangarkhaev/PycharmProjects/python_django/venv/lib/python3.11/site-packages/django/urls/resolvers.py", line 851, in _reverse_with_prefix
    raise NoReverseMatch(msg)
django.urls.exceptions.NoReverseMatch: Reverse for 'article_details' not found. 'article_details' is not a valid view function or pattern name.
2024-07-08 12:59:25,684 | INFO | django.utils.autoreload | Watching for file changes with StatReloader
2024-07-08 12:59:29,104 | WARNING | django.request | Not Found: /
2024-07-08 15:40:50,994 | INFO | django.utils.autoreload | /Users/moskvinangarkhaev/PycharmProjects/python_django/mysite/shopapp/models.py changed, reloading.
2024-07-08 15:40:51,747 | INFO | django.utils.autoreload | Watching for file changes with StatReloader
2024-07-08 15:40:58,102 | INFO | django.utils.autoreload | /Users/moskvinangarkhaev/PycharmProjects/python_django/mysite/shopapp/models.py changed, reloading.
2024-07-08 15:40:58,462 | INFO | django.utils.autoreload | Watching for file changes with StatReloader
2024-07-08 16:01:06,288 | INFO | django.utils.autoreload | Watching for file changes with StatReloader
2024-07-08 16:01:20,997 | INFO | django.utils.autoreload | /Users/moskvinangarkhaev/PycharmProjects/python_django/mysite/shopapp/sitemaps.py changed, reloading.
2024-07-08 16:01:21,365 | INFO | django.utils.autoreload | Watching for file changes with StatReloader
2024-07-08 16:01:24,477 | WARNING | django.request | Not Found: /
2024-07-08 16:01:31,658 | WARNING | django.request | Not Found: /sitemaps
2024-07-08 16:01:37,184 | WARNING | django.request | Not Found: /sitemap
2024-07-08 16:01:57,809 | WARNING | django.request | Not Found: /sitemap.xml
2024-07-08 16:02:33,141 | INFO | django.utils.autoreload | /Users/moskvinangarkhaev/PycharmProjects/python_django/mysite/mysite/urls.py changed, reloading.
2024-07-08 16:02:33,552 | INFO | django.utils.autoreload | Watching for file changes with StatReloader
2024-07-08 16:02:34,447 | ERROR | django.request | Internal Server Error: /sitemap.xml
Traceback (most recent call last):
  File "/Users/moskvinangarkhaev/PycharmProjects/python_django/venv/lib/python3.11/site-packages/django/core/handlers/exception.py", line 55, in inner
    response = get_response(request)
               ^^^^^^^^^^^^^^^^^^^^^
  File "/Users/moskvinangarkhaev/PycharmProjects/python_django/venv/lib/python3.11/site-packages/django/core/handlers/base.py", line 197, in _get_response
    response = wrapped_callback(request, *callback_args, **callback_kwargs)
               ^^^^^^^^^^^^^^^^^^^^^^^^^^^^^^^^^^^^^^^^^^^^^^^^^^^^^^^^^^^^
  File "/Users/moskvinangarkhaev/PycharmProjects/python_django/venv/lib/python3.11/site-packages/django/contrib/sitemaps/views.py", line 23, in inner
    response = func(request, *args, **kwargs)
               ^^^^^^^^^^^^^^^^^^^^^^^^^^^^^^
TypeError: sitemap() got an unexpected keyword argument 'Sitemaps'
2024-07-08 16:02:49,354 | INFO | django.utils.autoreload | /Users/moskvinangarkhaev/PycharmProjects/python_django/mysite/mysite/urls.py changed, reloading.
2024-07-08 16:02:49,747 | INFO | django.utils.autoreload | Watching for file changes with StatReloader
2024-07-08 16:03:14,744 | INFO | django.utils.autoreload | /Users/moskvinangarkhaev/PycharmProjects/python_django/mysite/mysite/urls.py changed, reloading.
2024-07-08 16:03:15,231 | INFO | django.utils.autoreload | Watching for file changes with StatReloader
2024-07-08 16:03:30,203 | ERROR | django.request | Internal Server Error: /sitemap.xml
Traceback (most recent call last):
  File "/Users/moskvinangarkhaev/PycharmProjects/python_django/venv/lib/python3.11/site-packages/django/core/handlers/exception.py", line 55, in inner
    response = get_response(request)
               ^^^^^^^^^^^^^^^^^^^^^
  File "/Users/moskvinangarkhaev/PycharmProjects/python_django/venv/lib/python3.11/site-packages/django/core/handlers/base.py", line 197, in _get_response
    response = wrapped_callback(request, *callback_args, **callback_kwargs)
               ^^^^^^^^^^^^^^^^^^^^^^^^^^^^^^^^^^^^^^^^^^^^^^^^^^^^^^^^^^^^
  File "/Users/moskvinangarkhaev/PycharmProjects/python_django/venv/lib/python3.11/site-packages/django/contrib/sitemaps/views.py", line 23, in inner
    response = func(request, *args, **kwargs)
               ^^^^^^^^^^^^^^^^^^^^^^^^^^^^^^
TypeError: sitemap() got an unexpected keyword argument 'Sitemaps'
2024-07-08 16:03:45,659 | INFO | django.utils.autoreload | /Users/moskvinangarkhaev/PycharmProjects/python_django/mysite/mysite/urls.py changed, reloading.
2024-07-08 16:03:46,049 | INFO | django.utils.autoreload | Watching for file changes with StatReloader
2024-07-08 16:05:24,880 | INFO | django.utils.autoreload | /Users/moskvinangarkhaev/PycharmProjects/python_django/mysite/mysite/urls.py changed, reloading.
2024-07-08 16:05:25,304 | INFO | django.utils.autoreload | Watching for file changes with StatReloader
2024-07-08 16:14:50,154 | INFO | django.utils.autoreload | /Users/moskvinangarkhaev/PycharmProjects/python_django/mysite/shopapp/views.py changed, reloading.
2024-07-08 16:14:50,762 | INFO | django.utils.autoreload | Watching for file changes with StatReloader
2024-07-08 16:18:21,283 | INFO | django.utils.autoreload | /Users/moskvinangarkhaev/PycharmProjects/python_django/mysite/shopapp/views.py changed, reloading.
2024-07-08 16:18:21,744 | INFO | django.utils.autoreload | Watching for file changes with StatReloader
2024-07-08 16:23:11,515 | INFO | django.utils.autoreload | /Users/moskvinangarkhaev/PycharmProjects/python_django/mysite/shopapp/views.py changed, reloading.
2024-07-08 16:23:11,961 | INFO | django.utils.autoreload | Watching for file changes with StatReloader
2024-07-08 16:25:50,477 | INFO | django.utils.autoreload | /Users/moskvinangarkhaev/PycharmProjects/python_django/mysite/shopapp/views.py changed, reloading.
2024-07-08 16:25:51,124 | INFO | django.utils.autoreload | Watching for file changes with StatReloader
2024-07-08 16:27:27,853 | INFO | django.utils.autoreload | /Users/moskvinangarkhaev/PycharmProjects/python_django/mysite/shopapp/urls.py changed, reloading.
2024-07-08 16:27:28,340 | INFO | django.utils.autoreload | Watching for file changes with StatReloader
2024-07-08 16:27:39,968 | INFO | django.utils.autoreload | /Users/moskvinangarkhaev/PycharmProjects/python_django/mysite/shopapp/urls.py changed, reloading.
2024-07-08 16:27:40,318 | INFO | django.utils.autoreload | Watching for file changes with StatReloader
2024-07-08 16:28:20,820 | WARNING | django.request | Not Found: /products/latest/feed
2024-07-08 16:29:13,454 | WARNING | django.request | Not Found: /shopapp/products/latest/feed
2024-07-08 16:35:00,037 | WARNING | django.request | Not Found: /favicon.ico
2024-07-08 16:45:57,774 | INFO | django.utils.autoreload | Watching for file changes with StatReloader
2024-07-08 16:54:31,331 | INFO | django.utils.autoreload | /Users/moskvinangarkhaev/PycharmProjects/python_django/mysite/shopapp/views.py changed, reloading.
2024-07-08 16:54:31,758 | INFO | django.utils.autoreload | Watching for file changes with StatReloader
2024-07-08 16:55:28,886 | INFO | django.utils.autoreload | /Users/moskvinangarkhaev/PycharmProjects/python_django/mysite/shopapp/views.py changed, reloading.
2024-07-08 16:55:29,315 | INFO | django.utils.autoreload | Watching for file changes with StatReloader
2024-07-08 16:56:04,836 | INFO | django.utils.autoreload | /Users/moskvinangarkhaev/PycharmProjects/python_django/mysite/shopapp/views.py changed, reloading.
2024-07-08 16:56:05,200 | INFO | django.utils.autoreload | Watching for file changes with StatReloader
2024-07-08 16:56:27,182 | INFO | django.utils.autoreload | /Users/moskvinangarkhaev/PycharmProjects/python_django/mysite/shopapp/views.py changed, reloading.
2024-07-08 16:56:27,554 | INFO | django.utils.autoreload | Watching for file changes with StatReloader
2024-07-08 16:56:43,471 | ERROR | django.request | Internal Server Error: /ru/shop/products/latest/feed
Traceback (most recent call last):
  File "/Users/moskvinangarkhaev/PycharmProjects/python_django/venv/lib/python3.11/site-packages/django/core/handlers/exception.py", line 55, in inner
    response = get_response(request)
               ^^^^^^^^^^^^^^^^^^^^^
  File "/Users/moskvinangarkhaev/PycharmProjects/python_django/venv/lib/python3.11/site-packages/django/core/handlers/base.py", line 197, in _get_response
    response = wrapped_callback(request, *callback_args, **callback_kwargs)
               ^^^^^^^^^^^^^^^^^^^^^^^^^^^^^^^^^^^^^^^^^^^^^^^^^^^^^^^^^^^^
  File "/Users/moskvinangarkhaev/PycharmProjects/python_django/venv/lib/python3.11/site-packages/django/contrib/syndication/views.py", line 40, in __call__
    feedgen = self.get_feed(obj, request)
              ^^^^^^^^^^^^^^^^^^^^^^^^^^^
  File "/Users/moskvinangarkhaev/PycharmProjects/python_django/venv/lib/python3.11/site-packages/django/contrib/syndication/views.py", line 194, in get_feed
    self._get_dynamic_attr("item_link", item),
    ^^^^^^^^^^^^^^^^^^^^^^^^^^^^^^^^^^^^^^^^^
  File "/Users/moskvinangarkhaev/PycharmProjects/python_django/venv/lib/python3.11/site-packages/django/contrib/syndication/views.py", line 103, in _get_dynamic_attr
    return attr(obj)
           ^^^^^^^^^
  File "/Users/moskvinangarkhaev/PycharmProjects/python_django/mysite/shopapp/views.py", line 58, in item_link
    return item.get_absolute_url(item.pk)
           ^^^^^^^^^^^^^^^^^^^^^^^^^^^^^^
TypeError: Product.get_absolute_url() takes 1 positional argument but 2 were given
2024-07-08 16:57:47,843 | ERROR | django.request | Internal Server Error: /ru/shop/products/latest/feed
Traceback (most recent call last):
  File "/Users/moskvinangarkhaev/PycharmProjects/python_django/venv/lib/python3.11/site-packages/django/core/handlers/exception.py", line 55, in inner
    response = get_response(request)
               ^^^^^^^^^^^^^^^^^^^^^
  File "/Users/moskvinangarkhaev/PycharmProjects/python_django/venv/lib/python3.11/site-packages/django/core/handlers/base.py", line 197, in _get_response
    response = wrapped_callback(request, *callback_args, **callback_kwargs)
               ^^^^^^^^^^^^^^^^^^^^^^^^^^^^^^^^^^^^^^^^^^^^^^^^^^^^^^^^^^^^
  File "/Users/moskvinangarkhaev/PycharmProjects/python_django/venv/lib/python3.11/site-packages/django/contrib/syndication/views.py", line 40, in __call__
    feedgen = self.get_feed(obj, request)
              ^^^^^^^^^^^^^^^^^^^^^^^^^^^
  File "/Users/moskvinangarkhaev/PycharmProjects/python_django/venv/lib/python3.11/site-packages/django/contrib/syndication/views.py", line 194, in get_feed
    self._get_dynamic_attr("item_link", item),
    ^^^^^^^^^^^^^^^^^^^^^^^^^^^^^^^^^^^^^^^^^
  File "/Users/moskvinangarkhaev/PycharmProjects/python_django/venv/lib/python3.11/site-packages/django/contrib/syndication/views.py", line 103, in _get_dynamic_attr
    return attr(obj)
           ^^^^^^^^^
  File "/Users/moskvinangarkhaev/PycharmProjects/python_django/mysite/shopapp/views.py", line 58, in item_link
    return item.get_absolute_url(item.pk)
           ^^^^^^^^^^^^^^^^^^^^^^^^^^^^^^
TypeError: Product.get_absolute_url() takes 1 positional argument but 2 were given
2024-07-08 16:58:28,685 | INFO | django.utils.autoreload | /Users/moskvinangarkhaev/PycharmProjects/python_django/mysite/shopapp/views.py changed, reloading.
2024-07-08 16:58:29,074 | INFO | django.utils.autoreload | Watching for file changes with StatReloader
2024-07-08 17:07:06,367 | INFO | django.utils.autoreload | Watching for file changes with StatReloader
2024-07-08 17:10:23,167 | WARNING | django.request | Not Found: /favicon.ico
2024-07-08 17:11:27,614 | INFO | django.utils.autoreload | /Users/moskvinangarkhaev/PycharmProjects/python_django/mysite/shopapp/views.py changed, reloading.
2024-07-08 17:11:27,988 | INFO | django.utils.autoreload | Watching for file changes with StatReloader
2024-07-08 17:11:43,733 | INFO | django.utils.autoreload | /Users/moskvinangarkhaev/PycharmProjects/python_django/mysite/shopapp/views.py changed, reloading.
2024-07-08 17:11:44,079 | INFO | django.utils.autoreload | Watching for file changes with StatReloader
2024-07-08 17:13:25,978 | INFO | django.utils.autoreload | /Users/moskvinangarkhaev/PycharmProjects/python_django/mysite/shopapp/views.py changed, reloading.
2024-07-08 17:13:26,340 | INFO | django.utils.autoreload | Watching for file changes with StatReloader
2024-07-08 17:14:12,877 | INFO | django.utils.autoreload | Watching for file changes with StatReloader
2024-07-08 18:01:02,771 | INFO | django.utils.autoreload | /Users/moskvinangarkhaev/PycharmProjects/python_django/mysite/shopapp/forms.py changed, reloading.
2024-07-08 18:01:03,235 | INFO | django.utils.autoreload | Watching for file changes with StatReloader
2024-07-08 18:03:37,094 | INFO | django.utils.autoreload | /Users/moskvinangarkhaev/PycharmProjects/python_django/mysite/shopapp/admin.py changed, reloading.
2024-07-08 18:03:37,473 | INFO | django.utils.autoreload | Watching for file changes with StatReloader
2024-07-08 18:08:48,863 | INFO | django.utils.autoreload | /Users/moskvinangarkhaev/PycharmProjects/python_django/mysite/shopapp/admin.py changed, reloading.
2024-07-08 18:08:49,266 | INFO | django.utils.autoreload | Watching for file changes with StatReloader
2024-07-08 18:16:11,123 | INFO | django.utils.autoreload | /Users/moskvinangarkhaev/PycharmProjects/python_django/mysite/shopapp/admin.py changed, reloading.
2024-07-08 18:16:11,577 | INFO | django.utils.autoreload | Watching for file changes with StatReloader
2024-07-08 18:17:17,055 | INFO | django.utils.autoreload | /Users/moskvinangarkhaev/PycharmProjects/python_django/mysite/shopapp/admin.py changed, reloading.
2024-07-08 18:17:17,567 | INFO | django.utils.autoreload | Watching for file changes with StatReloader
2024-07-08 18:19:15,257 | INFO | django.utils.autoreload | /Users/moskvinangarkhaev/PycharmProjects/python_django/mysite/shopapp/admin.py changed, reloading.
2024-07-08 18:19:15,640 | INFO | django.utils.autoreload | Watching for file changes with StatReloader
2024-07-08 18:19:39,616 | INFO | django.utils.autoreload | /Users/moskvinangarkhaev/PycharmProjects/python_django/mysite/shopapp/admin.py changed, reloading.
2024-07-08 18:19:40,012 | INFO | django.utils.autoreload | Watching for file changes with StatReloader
2024-07-08 18:23:31,380 | INFO | django.utils.autoreload | /Users/moskvinangarkhaev/PycharmProjects/python_django/mysite/shopapp/admin.py changed, reloading.
2024-07-08 18:23:31,851 | INFO | django.utils.autoreload | Watching for file changes with StatReloader
2024-07-08 18:24:41,083 | WARNING | django.request | Not Found: /admin/import-order-csv/
2024-07-08 18:26:09,266 | ERROR | django.request | Internal Server Error: /admin/shopapp/order/
Traceback (most recent call last):
  File "/Users/moskvinangarkhaev/PycharmProjects/python_django/venv/lib/python3.11/site-packages/django/core/handlers/exception.py", line 55, in inner
    response = get_response(request)
               ^^^^^^^^^^^^^^^^^^^^^
  File "/Users/moskvinangarkhaev/PycharmProjects/python_django/venv/lib/python3.11/site-packages/django/core/handlers/base.py", line 220, in _get_response
    response = response.render()
               ^^^^^^^^^^^^^^^^^
  File "/Users/moskvinangarkhaev/PycharmProjects/python_django/venv/lib/python3.11/site-packages/django/template/response.py", line 114, in render
    self.content = self.rendered_content
                   ^^^^^^^^^^^^^^^^^^^^^
  File "/Users/moskvinangarkhaev/PycharmProjects/python_django/venv/lib/python3.11/site-packages/django/template/response.py", line 90, in rendered_content
    template = self.resolve_template(self.template_name)
               ^^^^^^^^^^^^^^^^^^^^^^^^^^^^^^^^^^^^^^^^^
  File "/Users/moskvinangarkhaev/PycharmProjects/python_django/venv/lib/python3.11/site-packages/django/template/response.py", line 74, in resolve_template
    return get_template(template, using=self.using)
           ^^^^^^^^^^^^^^^^^^^^^^^^^^^^^^^^^^^^^^^^
  File "/Users/moskvinangarkhaev/PycharmProjects/python_django/venv/lib/python3.11/site-packages/django/template/loader.py", line 19, in get_template
    raise TemplateDoesNotExist(template_name, chain=chain)
django.template.exceptions.TemplateDoesNotExist: shopapp/orders_chagelist.html
2024-07-08 18:26:38,120 | INFO | django.utils.autoreload | /Users/moskvinangarkhaev/PycharmProjects/python_django/mysite/shopapp/admin.py changed, reloading.
2024-07-08 18:26:38,490 | INFO | django.utils.autoreload | Watching for file changes with StatReloader
2024-07-08 18:27:28,718 | INFO | django.utils.autoreload | /Users/moskvinangarkhaev/PycharmProjects/python_django/mysite/shopapp/admin.py changed, reloading.
2024-07-08 18:27:29,112 | INFO | django.utils.autoreload | Watching for file changes with StatReloader
2024-07-08 18:28:15,741 | WARNING | django.request | Not Found: /admin/shopapp/orders/
2024-07-08 18:29:00,756 | INFO | django.utils.autoreload | /Users/moskvinangarkhaev/PycharmProjects/python_django/mysite/shopapp/admin.py changed, reloading.
2024-07-08 18:29:01,128 | INFO | django.utils.autoreload | Watching for file changes with StatReloader
2024-07-08 18:31:55,831 | INFO | django.utils.autoreload | /Users/moskvinangarkhaev/PycharmProjects/python_django/mysite/shopapp/admin.py changed, reloading.
2024-07-08 18:31:56,241 | INFO | django.utils.autoreload | Watching for file changes with StatReloader
2024-07-08 18:32:41,095 | INFO | django.utils.autoreload | /Users/moskvinangarkhaev/PycharmProjects/python_django/mysite/shopapp/admin.py changed, reloading.
2024-07-08 18:32:41,469 | INFO | django.utils.autoreload | Watching for file changes with StatReloader
2024-07-08 18:37:23,616 | INFO | django.utils.autoreload | /Users/moskvinangarkhaev/PycharmProjects/python_django/mysite/shopapp/admin.py changed, reloading.
2024-07-08 18:37:24,131 | INFO | django.utils.autoreload | Watching for file changes with StatReloader
2024-07-08 18:38:25,610 | INFO | django.utils.autoreload | /Users/moskvinangarkhaev/PycharmProjects/python_django/mysite/shopapp/admin.py changed, reloading.
2024-07-08 18:38:26,005 | INFO | django.utils.autoreload | Watching for file changes with StatReloader
2024-07-08 18:47:53,964 | INFO | django.utils.autoreload | Watching for file changes with StatReloader
2024-07-08 18:48:13,170 | ERROR | django.request | Internal Server Error: /admin/shopapp/order/import-order-csv/
Traceback (most recent call last):
  File "/Users/moskvinangarkhaev/PycharmProjects/python_django/venv/lib/python3.11/site-packages/django/core/handlers/exception.py", line 55, in inner
    response = get_response(request)
               ^^^^^^^^^^^^^^^^^^^^^
  File "/Users/moskvinangarkhaev/PycharmProjects/python_django/venv/lib/python3.11/site-packages/django/core/handlers/base.py", line 197, in _get_response
    response = wrapped_callback(request, *callback_args, **callback_kwargs)
               ^^^^^^^^^^^^^^^^^^^^^^^^^^^^^^^^^^^^^^^^^^^^^^^^^^^^^^^^^^^^
  File "/Users/moskvinangarkhaev/PycharmProjects/python_django/mysite/shopapp/admin.py", line 108, in import_csv
    orders = [
             ^
  File "/Users/moskvinangarkhaev/PycharmProjects/python_django/mysite/shopapp/admin.py", line 109, in <listcomp>
    Order(**row)
TypeError: keywords must be strings
2024-07-08 18:49:05,387 | ERROR | django.request | Internal Server Error: /admin/shopapp/order/import-order-csv/
Traceback (most recent call last):
  File "/Users/moskvinangarkhaev/PycharmProjects/python_django/venv/lib/python3.11/site-packages/django/core/handlers/exception.py", line 55, in inner
    response = get_response(request)
               ^^^^^^^^^^^^^^^^^^^^^
  File "/Users/moskvinangarkhaev/PycharmProjects/python_django/venv/lib/python3.11/site-packages/django/core/handlers/base.py", line 197, in _get_response
    response = wrapped_callback(request, *callback_args, **callback_kwargs)
               ^^^^^^^^^^^^^^^^^^^^^^^^^^^^^^^^^^^^^^^^^^^^^^^^^^^^^^^^^^^^
  File "/Users/moskvinangarkhaev/PycharmProjects/python_django/mysite/shopapp/admin.py", line 108, in import_csv
    orders = [
             ^
  File "/Users/moskvinangarkhaev/PycharmProjects/python_django/mysite/shopapp/admin.py", line 109, in <listcomp>
    Order(**row)
TypeError: keywords must be strings
2024-07-08 18:57:47,913 | INFO | django.utils.autoreload | /Users/moskvinangarkhaev/PycharmProjects/python_django/mysite/shopapp/admin.py changed, reloading.
2024-07-08 18:57:48,295 | INFO | django.utils.autoreload | Watching for file changes with StatReloader
2024-07-08 18:58:31,142 | INFO | django.utils.autoreload | /Users/moskvinangarkhaev/PycharmProjects/python_django/mysite/shopapp/admin.py changed, reloading.
2024-07-08 18:58:31,548 | INFO | django.utils.autoreload | Watching for file changes with StatReloader
2024-07-08 18:59:34,069 | INFO | django.utils.autoreload | /Users/moskvinangarkhaev/PycharmProjects/python_django/mysite/shopapp/admin.py changed, reloading.
2024-07-08 19:01:52,404 | INFO | django.utils.autoreload | Watching for file changes with StatReloader
2024-07-08 19:02:21,944 | ERROR | django.request | Internal Server Error: /admin/shopapp/order/import-order-csv/
Traceback (most recent call last):
  File "/Users/moskvinangarkhaev/PycharmProjects/python_django/venv/lib/python3.11/site-packages/django/core/handlers/exception.py", line 55, in inner
    response = get_response(request)
               ^^^^^^^^^^^^^^^^^^^^^
  File "/Users/moskvinangarkhaev/PycharmProjects/python_django/venv/lib/python3.11/site-packages/django/core/handlers/base.py", line 197, in _get_response
    response = wrapped_callback(request, *callback_args, **callback_kwargs)
               ^^^^^^^^^^^^^^^^^^^^^^^^^^^^^^^^^^^^^^^^^^^^^^^^^^^^^^^^^^^^
  File "/Users/moskvinangarkhaev/PycharmProjects/python_django/mysite/shopapp/admin.py", line 118, in import_csv
    products_list = eval(row['products'])
                         ~~~^^^^^^^^^^^^
KeyError: 'products'
2024-07-08 19:03:01,266 | INFO | django.utils.autoreload | /Users/moskvinangarkhaev/PycharmProjects/python_django/mysite/shopapp/admin.py changed, reloading.
2024-07-08 19:03:01,847 | INFO | django.utils.autoreload | Watching for file changes with StatReloader
2024-07-08 19:04:24,070 | INFO | django.utils.autoreload | /Users/moskvinangarkhaev/PycharmProjects/python_django/mysite/shopapp/admin.py changed, reloading.
2024-07-08 19:04:24,467 | INFO | django.utils.autoreload | Watching for file changes with StatReloader
2024-07-08 19:04:42,956 | ERROR | django.request | Internal Server Error: /admin/shopapp/order/import-order-csv/
Traceback (most recent call last):
  File "/Users/moskvinangarkhaev/PycharmProjects/python_django/venv/lib/python3.11/site-packages/django/db/backends/utils.py", line 105, in _execute
    return self.cursor.execute(sql, params)
           ^^^^^^^^^^^^^^^^^^^^^^^^^^^^^^^^
  File "/Users/moskvinangarkhaev/PycharmProjects/python_django/venv/lib/python3.11/site-packages/django/db/backends/sqlite3/base.py", line 329, in execute
    return super().execute(query, params)
           ^^^^^^^^^^^^^^^^^^^^^^^^^^^^^^
sqlite3.OperationalError: database is locked

The above exception was the direct cause of the following exception:

Traceback (most recent call last):
  File "/Users/moskvinangarkhaev/PycharmProjects/python_django/venv/lib/python3.11/site-packages/django/core/handlers/exception.py", line 55, in inner
    response = get_response(request)
               ^^^^^^^^^^^^^^^^^^^^^
  File "/Users/moskvinangarkhaev/PycharmProjects/python_django/venv/lib/python3.11/site-packages/django/core/handlers/base.py", line 197, in _get_response
    response = wrapped_callback(request, *callback_args, **callback_kwargs)
               ^^^^^^^^^^^^^^^^^^^^^^^^^^^^^^^^^^^^^^^^^^^^^^^^^^^^^^^^^^^^
  File "/Users/moskvinangarkhaev/PycharmProjects/python_django/mysite/shopapp/admin.py", line 127, in import_csv
    order.save()
  File "/Users/moskvinangarkhaev/PycharmProjects/python_django/venv/lib/python3.11/site-packages/django/db/models/base.py", line 822, in save
    self.save_base(
  File "/Users/moskvinangarkhaev/PycharmProjects/python_django/venv/lib/python3.11/site-packages/django/db/models/base.py", line 909, in save_base
    updated = self._save_table(
              ^^^^^^^^^^^^^^^^^
  File "/Users/moskvinangarkhaev/PycharmProjects/python_django/venv/lib/python3.11/site-packages/django/db/models/base.py", line 1071, in _save_table
    results = self._do_insert(
              ^^^^^^^^^^^^^^^^
  File "/Users/moskvinangarkhaev/PycharmProjects/python_django/venv/lib/python3.11/site-packages/django/db/models/base.py", line 1112, in _do_insert
    return manager._insert(
           ^^^^^^^^^^^^^^^^
  File "/Users/moskvinangarkhaev/PycharmProjects/python_django/venv/lib/python3.11/site-packages/django/db/models/manager.py", line 87, in manager_method
    return getattr(self.get_queryset(), name)(*args, **kwargs)
           ^^^^^^^^^^^^^^^^^^^^^^^^^^^^^^^^^^^^^^^^^^^^^^^^^^^
  File "/Users/moskvinangarkhaev/PycharmProjects/python_django/venv/lib/python3.11/site-packages/django/db/models/query.py", line 1847, in _insert
    return query.get_compiler(using=using).execute_sql(returning_fields)
           ^^^^^^^^^^^^^^^^^^^^^^^^^^^^^^^^^^^^^^^^^^^^^^^^^^^^^^^^^^^^^
  File "/Users/moskvinangarkhaev/PycharmProjects/python_django/venv/lib/python3.11/site-packages/django/db/models/sql/compiler.py", line 1823, in execute_sql
    cursor.execute(sql, params)
  File "/Users/moskvinangarkhaev/PycharmProjects/python_django/venv/lib/python3.11/site-packages/debug_toolbar/panels/sql/tracking.py", line 235, in execute
    return self._record(super().execute, sql, params)
           ^^^^^^^^^^^^^^^^^^^^^^^^^^^^^^^^^^^^^^^^^^
  File "/Users/moskvinangarkhaev/PycharmProjects/python_django/venv/lib/python3.11/site-packages/debug_toolbar/panels/sql/tracking.py", line 160, in _record
    return method(sql, params)
           ^^^^^^^^^^^^^^^^^^^
  File "/Users/moskvinangarkhaev/PycharmProjects/python_django/venv/lib/python3.11/site-packages/django/db/backends/utils.py", line 122, in execute
    return super().execute(sql, params)
           ^^^^^^^^^^^^^^^^^^^^^^^^^^^^
  File "/Users/moskvinangarkhaev/PycharmProjects/python_django/venv/lib/python3.11/site-packages/django/db/backends/utils.py", line 79, in execute
    return self._execute_with_wrappers(
           ^^^^^^^^^^^^^^^^^^^^^^^^^^^^
  File "/Users/moskvinangarkhaev/PycharmProjects/python_django/venv/lib/python3.11/site-packages/django/db/backends/utils.py", line 92, in _execute_with_wrappers
    return executor(sql, params, many, context)
           ^^^^^^^^^^^^^^^^^^^^^^^^^^^^^^^^^^^^
  File "/Users/moskvinangarkhaev/PycharmProjects/python_django/venv/lib/python3.11/site-packages/django/db/backends/utils.py", line 100, in _execute
    with self.db.wrap_database_errors:
  File "/Users/moskvinangarkhaev/PycharmProjects/python_django/venv/lib/python3.11/site-packages/django/db/utils.py", line 91, in __exit__
    raise dj_exc_value.with_traceback(traceback) from exc_value
  File "/Users/moskvinangarkhaev/PycharmProjects/python_django/venv/lib/python3.11/site-packages/django/db/backends/utils.py", line 105, in _execute
    return self.cursor.execute(sql, params)
           ^^^^^^^^^^^^^^^^^^^^^^^^^^^^^^^^
  File "/Users/moskvinangarkhaev/PycharmProjects/python_django/venv/lib/python3.11/site-packages/django/db/backends/sqlite3/base.py", line 329, in execute
    return super().execute(query, params)
           ^^^^^^^^^^^^^^^^^^^^^^^^^^^^^^
django.db.utils.OperationalError: database is locked
2024-07-08 19:05:15,627 | INFO | django.utils.autoreload | /Users/moskvinangarkhaev/PycharmProjects/python_django/mysite/shopapp/admin.py changed, reloading.
2024-07-08 19:05:16,032 | INFO | django.utils.autoreload | Watching for file changes with StatReloader
2024-07-08 19:05:24,811 | ERROR | django.request | Internal Server Error: /admin/shopapp/order/import-order-csv/
Traceback (most recent call last):
  File "/Users/moskvinangarkhaev/PycharmProjects/python_django/venv/lib/python3.11/site-packages/django/db/backends/utils.py", line 105, in _execute
    return self.cursor.execute(sql, params)
           ^^^^^^^^^^^^^^^^^^^^^^^^^^^^^^^^
  File "/Users/moskvinangarkhaev/PycharmProjects/python_django/venv/lib/python3.11/site-packages/django/db/backends/sqlite3/base.py", line 329, in execute
    return super().execute(query, params)
           ^^^^^^^^^^^^^^^^^^^^^^^^^^^^^^
sqlite3.OperationalError: database is locked

The above exception was the direct cause of the following exception:

Traceback (most recent call last):
  File "/Users/moskvinangarkhaev/PycharmProjects/python_django/venv/lib/python3.11/site-packages/django/core/handlers/exception.py", line 55, in inner
    response = get_response(request)
               ^^^^^^^^^^^^^^^^^^^^^
  File "/Users/moskvinangarkhaev/PycharmProjects/python_django/venv/lib/python3.11/site-packages/django/core/handlers/base.py", line 197, in _get_response
    response = wrapped_callback(request, *callback_args, **callback_kwargs)
               ^^^^^^^^^^^^^^^^^^^^^^^^^^^^^^^^^^^^^^^^^^^^^^^^^^^^^^^^^^^^
  File "/Users/moskvinangarkhaev/PycharmProjects/python_django/mysite/shopapp/admin.py", line 127, in import_csv
    order.save()
  File "/Users/moskvinangarkhaev/PycharmProjects/python_django/venv/lib/python3.11/site-packages/django/db/models/base.py", line 822, in save
    self.save_base(
  File "/Users/moskvinangarkhaev/PycharmProjects/python_django/venv/lib/python3.11/site-packages/django/db/models/base.py", line 909, in save_base
    updated = self._save_table(
              ^^^^^^^^^^^^^^^^^
  File "/Users/moskvinangarkhaev/PycharmProjects/python_django/venv/lib/python3.11/site-packages/django/db/models/base.py", line 1071, in _save_table
    results = self._do_insert(
              ^^^^^^^^^^^^^^^^
  File "/Users/moskvinangarkhaev/PycharmProjects/python_django/venv/lib/python3.11/site-packages/django/db/models/base.py", line 1112, in _do_insert
    return manager._insert(
           ^^^^^^^^^^^^^^^^
  File "/Users/moskvinangarkhaev/PycharmProjects/python_django/venv/lib/python3.11/site-packages/django/db/models/manager.py", line 87, in manager_method
    return getattr(self.get_queryset(), name)(*args, **kwargs)
           ^^^^^^^^^^^^^^^^^^^^^^^^^^^^^^^^^^^^^^^^^^^^^^^^^^^
  File "/Users/moskvinangarkhaev/PycharmProjects/python_django/venv/lib/python3.11/site-packages/django/db/models/query.py", line 1847, in _insert
    return query.get_compiler(using=using).execute_sql(returning_fields)
           ^^^^^^^^^^^^^^^^^^^^^^^^^^^^^^^^^^^^^^^^^^^^^^^^^^^^^^^^^^^^^
  File "/Users/moskvinangarkhaev/PycharmProjects/python_django/venv/lib/python3.11/site-packages/django/db/models/sql/compiler.py", line 1823, in execute_sql
    cursor.execute(sql, params)
  File "/Users/moskvinangarkhaev/PycharmProjects/python_django/venv/lib/python3.11/site-packages/debug_toolbar/panels/sql/tracking.py", line 235, in execute
    return self._record(super().execute, sql, params)
           ^^^^^^^^^^^^^^^^^^^^^^^^^^^^^^^^^^^^^^^^^^
  File "/Users/moskvinangarkhaev/PycharmProjects/python_django/venv/lib/python3.11/site-packages/debug_toolbar/panels/sql/tracking.py", line 160, in _record
    return method(sql, params)
           ^^^^^^^^^^^^^^^^^^^
  File "/Users/moskvinangarkhaev/PycharmProjects/python_django/venv/lib/python3.11/site-packages/django/db/backends/utils.py", line 122, in execute
    return super().execute(sql, params)
           ^^^^^^^^^^^^^^^^^^^^^^^^^^^^
  File "/Users/moskvinangarkhaev/PycharmProjects/python_django/venv/lib/python3.11/site-packages/django/db/backends/utils.py", line 79, in execute
    return self._execute_with_wrappers(
           ^^^^^^^^^^^^^^^^^^^^^^^^^^^^
  File "/Users/moskvinangarkhaev/PycharmProjects/python_django/venv/lib/python3.11/site-packages/django/db/backends/utils.py", line 92, in _execute_with_wrappers
    return executor(sql, params, many, context)
           ^^^^^^^^^^^^^^^^^^^^^^^^^^^^^^^^^^^^
  File "/Users/moskvinangarkhaev/PycharmProjects/python_django/venv/lib/python3.11/site-packages/django/db/backends/utils.py", line 100, in _execute
    with self.db.wrap_database_errors:
  File "/Users/moskvinangarkhaev/PycharmProjects/python_django/venv/lib/python3.11/site-packages/django/db/utils.py", line 91, in __exit__
    raise dj_exc_value.with_traceback(traceback) from exc_value
  File "/Users/moskvinangarkhaev/PycharmProjects/python_django/venv/lib/python3.11/site-packages/django/db/backends/utils.py", line 105, in _execute
    return self.cursor.execute(sql, params)
           ^^^^^^^^^^^^^^^^^^^^^^^^^^^^^^^^
  File "/Users/moskvinangarkhaev/PycharmProjects/python_django/venv/lib/python3.11/site-packages/django/db/backends/sqlite3/base.py", line 329, in execute
    return super().execute(query, params)
           ^^^^^^^^^^^^^^^^^^^^^^^^^^^^^^
django.db.utils.OperationalError: database is locked
2024-07-08 19:06:21,970 | ERROR | django.request | Internal Server Error: /admin/shopapp/order/import-order-csv/
Traceback (most recent call last):
  File "/Users/moskvinangarkhaev/PycharmProjects/python_django/venv/lib/python3.11/site-packages/django/db/models/fields/__init__.py", line 2117, in get_prep_value
    return int(value)
           ^^^^^^^^^^
TypeError: int() argument must be a string, a bytes-like object or a real number, not 'types.GenericAlias'

The above exception was the direct cause of the following exception:

Traceback (most recent call last):
  File "/Users/moskvinangarkhaev/PycharmProjects/python_django/venv/lib/python3.11/site-packages/django/core/handlers/exception.py", line 55, in inner
    response = get_response(request)
               ^^^^^^^^^^^^^^^^^^^^^
  File "/Users/moskvinangarkhaev/PycharmProjects/python_django/venv/lib/python3.11/site-packages/django/core/handlers/base.py", line 197, in _get_response
    response = wrapped_callback(request, *callback_args, **callback_kwargs)
               ^^^^^^^^^^^^^^^^^^^^^^^^^^^^^^^^^^^^^^^^^^^^^^^^^^^^^^^^^^^^
  File "/Users/moskvinangarkhaev/PycharmProjects/python_django/mysite/shopapp/admin.py", line 129, in import_csv
    products = Product.objects.filter(id__in=products_list)
               ^^^^^^^^^^^^^^^^^^^^^^^^^^^^^^^^^^^^^^^^^^^^
  File "/Users/moskvinangarkhaev/PycharmProjects/python_django/venv/lib/python3.11/site-packages/django/db/models/manager.py", line 87, in manager_method
    return getattr(self.get_queryset(), name)(*args, **kwargs)
           ^^^^^^^^^^^^^^^^^^^^^^^^^^^^^^^^^^^^^^^^^^^^^^^^^^^
  File "/Users/moskvinangarkhaev/PycharmProjects/python_django/venv/lib/python3.11/site-packages/django/db/models/query.py", line 1476, in filter
    return self._filter_or_exclude(False, args, kwargs)
           ^^^^^^^^^^^^^^^^^^^^^^^^^^^^^^^^^^^^^^^^^^^^
  File "/Users/moskvinangarkhaev/PycharmProjects/python_django/venv/lib/python3.11/site-packages/django/db/models/query.py", line 1494, in _filter_or_exclude
    clone._filter_or_exclude_inplace(negate, args, kwargs)
  File "/Users/moskvinangarkhaev/PycharmProjects/python_django/venv/lib/python3.11/site-packages/django/db/models/query.py", line 1501, in _filter_or_exclude_inplace
    self._query.add_q(Q(*args, **kwargs))
  File "/Users/moskvinangarkhaev/PycharmProjects/python_django/venv/lib/python3.11/site-packages/django/db/models/sql/query.py", line 1613, in add_q
    clause, _ = self._add_q(q_object, self.used_aliases)
                ^^^^^^^^^^^^^^^^^^^^^^^^^^^^^^^^^^^^^^^^
  File "/Users/moskvinangarkhaev/PycharmProjects/python_django/venv/lib/python3.11/site-packages/django/db/models/sql/query.py", line 1645, in _add_q
    child_clause, needed_inner = self.build_filter(
                                 ^^^^^^^^^^^^^^^^^^
  File "/Users/moskvinangarkhaev/PycharmProjects/python_django/venv/lib/python3.11/site-packages/django/db/models/sql/query.py", line 1559, in build_filter
    condition = self.build_lookup(lookups, col, value)
                ^^^^^^^^^^^^^^^^^^^^^^^^^^^^^^^^^^^^^^
  File "/Users/moskvinangarkhaev/PycharmProjects/python_django/venv/lib/python3.11/site-packages/django/db/models/sql/query.py", line 1389, in build_lookup
    lookup = lookup_class(lhs, rhs)
             ^^^^^^^^^^^^^^^^^^^^^^
  File "/Users/moskvinangarkhaev/PycharmProjects/python_django/venv/lib/python3.11/site-packages/django/db/models/lookups.py", line 30, in __init__
    self.rhs = self.get_prep_lookup()
               ^^^^^^^^^^^^^^^^^^^^^^
  File "/Users/moskvinangarkhaev/PycharmProjects/python_django/venv/lib/python3.11/site-packages/django/db/models/lookups.py", line 484, in get_prep_lookup
    return super().get_prep_lookup()
           ^^^^^^^^^^^^^^^^^^^^^^^^^
  File "/Users/moskvinangarkhaev/PycharmProjects/python_django/venv/lib/python3.11/site-packages/django/db/models/lookups.py", line 299, in get_prep_lookup
    rhs_value = self.lhs.output_field.get_prep_value(rhs_value)
                ^^^^^^^^^^^^^^^^^^^^^^^^^^^^^^^^^^^^^^^^^^^^^^^
  File "/Users/moskvinangarkhaev/PycharmProjects/python_django/venv/lib/python3.11/site-packages/django/db/models/fields/__init__.py", line 2119, in get_prep_value
    raise e.__class__(
TypeError: Field 'id' expected a number but got *list['[1, 2, 3]'].
2024-07-08 19:07:44,083 | INFO | django.utils.autoreload | /Users/moskvinangarkhaev/PycharmProjects/python_django/mysite/shopapp/admin.py changed, reloading.
2024-07-08 19:07:44,501 | INFO | django.utils.autoreload | Watching for file changes with StatReloader
2024-07-08 19:08:05,552 | INFO | django.utils.autoreload | /Users/moskvinangarkhaev/PycharmProjects/python_django/mysite/shopapp/admin.py changed, reloading.
2024-07-08 19:08:05,909 | INFO | django.utils.autoreload | Watching for file changes with StatReloader
2024-07-08 19:08:12,867 | ERROR | django.request | Internal Server Error: /admin/shopapp/order/import-order-csv/
Traceback (most recent call last):
  File "/Users/moskvinangarkhaev/PycharmProjects/python_django/venv/lib/python3.11/site-packages/django/db/models/fields/__init__.py", line 2117, in get_prep_value
    return int(value)
           ^^^^^^^^^^
ValueError: invalid literal for int() with base 10: '['

The above exception was the direct cause of the following exception:

Traceback (most recent call last):
  File "/Users/moskvinangarkhaev/PycharmProjects/python_django/venv/lib/python3.11/site-packages/django/core/handlers/exception.py", line 55, in inner
    response = get_response(request)
               ^^^^^^^^^^^^^^^^^^^^^
  File "/Users/moskvinangarkhaev/PycharmProjects/python_django/venv/lib/python3.11/site-packages/django/core/handlers/base.py", line 197, in _get_response
    response = wrapped_callback(request, *callback_args, **callback_kwargs)
               ^^^^^^^^^^^^^^^^^^^^^^^^^^^^^^^^^^^^^^^^^^^^^^^^^^^^^^^^^^^^
  File "/Users/moskvinangarkhaev/PycharmProjects/python_django/mysite/shopapp/admin.py", line 129, in import_csv
    products = Product.objects.filter(id__in=products_list)
               ^^^^^^^^^^^^^^^^^^^^^^^^^^^^^^^^^^^^^^^^^^^^
  File "/Users/moskvinangarkhaev/PycharmProjects/python_django/venv/lib/python3.11/site-packages/django/db/models/manager.py", line 87, in manager_method
    return getattr(self.get_queryset(), name)(*args, **kwargs)
           ^^^^^^^^^^^^^^^^^^^^^^^^^^^^^^^^^^^^^^^^^^^^^^^^^^^
  File "/Users/moskvinangarkhaev/PycharmProjects/python_django/venv/lib/python3.11/site-packages/django/db/models/query.py", line 1476, in filter
    return self._filter_or_exclude(False, args, kwargs)
           ^^^^^^^^^^^^^^^^^^^^^^^^^^^^^^^^^^^^^^^^^^^^
  File "/Users/moskvinangarkhaev/PycharmProjects/python_django/venv/lib/python3.11/site-packages/django/db/models/query.py", line 1494, in _filter_or_exclude
    clone._filter_or_exclude_inplace(negate, args, kwargs)
  File "/Users/moskvinangarkhaev/PycharmProjects/python_django/venv/lib/python3.11/site-packages/django/db/models/query.py", line 1501, in _filter_or_exclude_inplace
    self._query.add_q(Q(*args, **kwargs))
  File "/Users/moskvinangarkhaev/PycharmProjects/python_django/venv/lib/python3.11/site-packages/django/db/models/sql/query.py", line 1613, in add_q
    clause, _ = self._add_q(q_object, self.used_aliases)
                ^^^^^^^^^^^^^^^^^^^^^^^^^^^^^^^^^^^^^^^^
  File "/Users/moskvinangarkhaev/PycharmProjects/python_django/venv/lib/python3.11/site-packages/django/db/models/sql/query.py", line 1645, in _add_q
    child_clause, needed_inner = self.build_filter(
                                 ^^^^^^^^^^^^^^^^^^
  File "/Users/moskvinangarkhaev/PycharmProjects/python_django/venv/lib/python3.11/site-packages/django/db/models/sql/query.py", line 1559, in build_filter
    condition = self.build_lookup(lookups, col, value)
                ^^^^^^^^^^^^^^^^^^^^^^^^^^^^^^^^^^^^^^
  File "/Users/moskvinangarkhaev/PycharmProjects/python_django/venv/lib/python3.11/site-packages/django/db/models/sql/query.py", line 1389, in build_lookup
    lookup = lookup_class(lhs, rhs)
             ^^^^^^^^^^^^^^^^^^^^^^
  File "/Users/moskvinangarkhaev/PycharmProjects/python_django/venv/lib/python3.11/site-packages/django/db/models/lookups.py", line 30, in __init__
    self.rhs = self.get_prep_lookup()
               ^^^^^^^^^^^^^^^^^^^^^^
  File "/Users/moskvinangarkhaev/PycharmProjects/python_django/venv/lib/python3.11/site-packages/django/db/models/lookups.py", line 484, in get_prep_lookup
    return super().get_prep_lookup()
           ^^^^^^^^^^^^^^^^^^^^^^^^^
  File "/Users/moskvinangarkhaev/PycharmProjects/python_django/venv/lib/python3.11/site-packages/django/db/models/lookups.py", line 299, in get_prep_lookup
    rhs_value = self.lhs.output_field.get_prep_value(rhs_value)
                ^^^^^^^^^^^^^^^^^^^^^^^^^^^^^^^^^^^^^^^^^^^^^^^
  File "/Users/moskvinangarkhaev/PycharmProjects/python_django/venv/lib/python3.11/site-packages/django/db/models/fields/__init__.py", line 2119, in get_prep_value
    raise e.__class__(
ValueError: Field 'id' expected a number but got '['.
2024-07-08 19:11:43,399 | INFO | django.utils.autoreload | /Users/moskvinangarkhaev/PycharmProjects/python_django/mysite/shopapp/admin.py changed, reloading.
2024-07-08 19:11:43,791 | INFO | django.utils.autoreload | Watching for file changes with StatReloader
2024-07-08 19:12:12,034 | INFO | django.utils.autoreload | /Users/moskvinangarkhaev/PycharmProjects/python_django/mysite/shopapp/admin.py changed, reloading.
2024-07-08 19:12:12,399 | INFO | django.utils.autoreload | Watching for file changes with StatReloader
2024-07-08 19:12:22,950 | INFO | django.utils.autoreload | /Users/moskvinangarkhaev/PycharmProjects/python_django/mysite/shopapp/admin.py changed, reloading.
2024-07-08 19:12:23,386 | INFO | django.utils.autoreload | Watching for file changes with StatReloader
2024-07-08 19:12:29,822 | INFO | django.utils.autoreload | /Users/moskvinangarkhaev/PycharmProjects/python_django/mysite/shopapp/admin.py changed, reloading.
2024-07-08 19:12:30,179 | INFO | django.utils.autoreload | Watching for file changes with StatReloader
2024-07-08 19:12:51,043 | ERROR | django.request | Internal Server Error: /admin/shopapp/order/import-order-csv/
Traceback (most recent call last):
  File "/Users/moskvinangarkhaev/PycharmProjects/python_django/venv/lib/python3.11/site-packages/django/db/backends/utils.py", line 105, in _execute
    return self.cursor.execute(sql, params)
           ^^^^^^^^^^^^^^^^^^^^^^^^^^^^^^^^
  File "/Users/moskvinangarkhaev/PycharmProjects/python_django/venv/lib/python3.11/site-packages/django/db/backends/sqlite3/base.py", line 329, in execute
    return super().execute(query, params)
           ^^^^^^^^^^^^^^^^^^^^^^^^^^^^^^
sqlite3.IntegrityError: UNIQUE constraint failed: shopapp_order.id

The above exception was the direct cause of the following exception:

Traceback (most recent call last):
  File "/Users/moskvinangarkhaev/PycharmProjects/python_django/venv/lib/python3.11/site-packages/django/core/handlers/exception.py", line 55, in inner
    response = get_response(request)
               ^^^^^^^^^^^^^^^^^^^^^
  File "/Users/moskvinangarkhaev/PycharmProjects/python_django/venv/lib/python3.11/site-packages/django/core/handlers/base.py", line 197, in _get_response
    response = wrapped_callback(request, *callback_args, **callback_kwargs)
               ^^^^^^^^^^^^^^^^^^^^^^^^^^^^^^^^^^^^^^^^^^^^^^^^^^^^^^^^^^^^
  File "/Users/moskvinangarkhaev/PycharmProjects/python_django/mysite/shopapp/admin.py", line 133, in import_csv
    Order.objects.bulk_create(orders)
  File "/Users/moskvinangarkhaev/PycharmProjects/python_django/venv/lib/python3.11/site-packages/django/db/models/manager.py", line 87, in manager_method
    return getattr(self.get_queryset(), name)(*args, **kwargs)
           ^^^^^^^^^^^^^^^^^^^^^^^^^^^^^^^^^^^^^^^^^^^^^^^^^^^
  File "/Users/moskvinangarkhaev/PycharmProjects/python_django/venv/lib/python3.11/site-packages/django/db/models/query.py", line 818, in bulk_create
    returned_columns = self._batched_insert(
                       ^^^^^^^^^^^^^^^^^^^^^
  File "/Users/moskvinangarkhaev/PycharmProjects/python_django/venv/lib/python3.11/site-packages/django/db/models/query.py", line 1875, in _batched_insert
    self._insert(
  File "/Users/moskvinangarkhaev/PycharmProjects/python_django/venv/lib/python3.11/site-packages/django/db/models/query.py", line 1847, in _insert
    return query.get_compiler(using=using).execute_sql(returning_fields)
           ^^^^^^^^^^^^^^^^^^^^^^^^^^^^^^^^^^^^^^^^^^^^^^^^^^^^^^^^^^^^^
  File "/Users/moskvinangarkhaev/PycharmProjects/python_django/venv/lib/python3.11/site-packages/django/db/models/sql/compiler.py", line 1823, in execute_sql
    cursor.execute(sql, params)
  File "/Users/moskvinangarkhaev/PycharmProjects/python_django/venv/lib/python3.11/site-packages/debug_toolbar/panels/sql/tracking.py", line 235, in execute
    return self._record(super().execute, sql, params)
           ^^^^^^^^^^^^^^^^^^^^^^^^^^^^^^^^^^^^^^^^^^
  File "/Users/moskvinangarkhaev/PycharmProjects/python_django/venv/lib/python3.11/site-packages/debug_toolbar/panels/sql/tracking.py", line 160, in _record
    return method(sql, params)
           ^^^^^^^^^^^^^^^^^^^
  File "/Users/moskvinangarkhaev/PycharmProjects/python_django/venv/lib/python3.11/site-packages/django/db/backends/utils.py", line 122, in execute
    return super().execute(sql, params)
           ^^^^^^^^^^^^^^^^^^^^^^^^^^^^
  File "/Users/moskvinangarkhaev/PycharmProjects/python_django/venv/lib/python3.11/site-packages/django/db/backends/utils.py", line 79, in execute
    return self._execute_with_wrappers(
           ^^^^^^^^^^^^^^^^^^^^^^^^^^^^
  File "/Users/moskvinangarkhaev/PycharmProjects/python_django/venv/lib/python3.11/site-packages/django/db/backends/utils.py", line 92, in _execute_with_wrappers
    return executor(sql, params, many, context)
           ^^^^^^^^^^^^^^^^^^^^^^^^^^^^^^^^^^^^
  File "/Users/moskvinangarkhaev/PycharmProjects/python_django/venv/lib/python3.11/site-packages/django/db/backends/utils.py", line 100, in _execute
    with self.db.wrap_database_errors:
  File "/Users/moskvinangarkhaev/PycharmProjects/python_django/venv/lib/python3.11/site-packages/django/db/utils.py", line 91, in __exit__
    raise dj_exc_value.with_traceback(traceback) from exc_value
  File "/Users/moskvinangarkhaev/PycharmProjects/python_django/venv/lib/python3.11/site-packages/django/db/backends/utils.py", line 105, in _execute
    return self.cursor.execute(sql, params)
           ^^^^^^^^^^^^^^^^^^^^^^^^^^^^^^^^
  File "/Users/moskvinangarkhaev/PycharmProjects/python_django/venv/lib/python3.11/site-packages/django/db/backends/sqlite3/base.py", line 329, in execute
    return super().execute(query, params)
           ^^^^^^^^^^^^^^^^^^^^^^^^^^^^^^
django.db.utils.IntegrityError: UNIQUE constraint failed: shopapp_order.id
2024-07-08 19:17:45,437 | INFO | django.utils.autoreload | Watching for file changes with StatReloader
2024-07-08 19:17:57,651 | ERROR | django.request | Internal Server Error: /admin/shopapp/order/import-order-csv/
Traceback (most recent call last):
  File "/Users/moskvinangarkhaev/PycharmProjects/python_django/venv/lib/python3.11/site-packages/django/db/backends/utils.py", line 105, in _execute
    return self.cursor.execute(sql, params)
           ^^^^^^^^^^^^^^^^^^^^^^^^^^^^^^^^
  File "/Users/moskvinangarkhaev/PycharmProjects/python_django/venv/lib/python3.11/site-packages/django/db/backends/sqlite3/base.py", line 329, in execute
    return super().execute(query, params)
           ^^^^^^^^^^^^^^^^^^^^^^^^^^^^^^
sqlite3.IntegrityError: UNIQUE constraint failed: shopapp_order.id

The above exception was the direct cause of the following exception:

Traceback (most recent call last):
  File "/Users/moskvinangarkhaev/PycharmProjects/python_django/venv/lib/python3.11/site-packages/django/core/handlers/exception.py", line 55, in inner
    response = get_response(request)
               ^^^^^^^^^^^^^^^^^^^^^
  File "/Users/moskvinangarkhaev/PycharmProjects/python_django/venv/lib/python3.11/site-packages/django/core/handlers/base.py", line 197, in _get_response
    response = wrapped_callback(request, *callback_args, **callback_kwargs)
               ^^^^^^^^^^^^^^^^^^^^^^^^^^^^^^^^^^^^^^^^^^^^^^^^^^^^^^^^^^^^
  File "/Users/moskvinangarkhaev/PycharmProjects/python_django/mysite/shopapp/admin.py", line 133, in import_csv
    Order.objects.bulk_create(orders)
  File "/Users/moskvinangarkhaev/PycharmProjects/python_django/venv/lib/python3.11/site-packages/django/db/models/manager.py", line 87, in manager_method
    return getattr(self.get_queryset(), name)(*args, **kwargs)
           ^^^^^^^^^^^^^^^^^^^^^^^^^^^^^^^^^^^^^^^^^^^^^^^^^^^
  File "/Users/moskvinangarkhaev/PycharmProjects/python_django/venv/lib/python3.11/site-packages/django/db/models/query.py", line 818, in bulk_create
    returned_columns = self._batched_insert(
                       ^^^^^^^^^^^^^^^^^^^^^
  File "/Users/moskvinangarkhaev/PycharmProjects/python_django/venv/lib/python3.11/site-packages/django/db/models/query.py", line 1875, in _batched_insert
    self._insert(
  File "/Users/moskvinangarkhaev/PycharmProjects/python_django/venv/lib/python3.11/site-packages/django/db/models/query.py", line 1847, in _insert
    return query.get_compiler(using=using).execute_sql(returning_fields)
           ^^^^^^^^^^^^^^^^^^^^^^^^^^^^^^^^^^^^^^^^^^^^^^^^^^^^^^^^^^^^^
  File "/Users/moskvinangarkhaev/PycharmProjects/python_django/venv/lib/python3.11/site-packages/django/db/models/sql/compiler.py", line 1823, in execute_sql
    cursor.execute(sql, params)
  File "/Users/moskvinangarkhaev/PycharmProjects/python_django/venv/lib/python3.11/site-packages/debug_toolbar/panels/sql/tracking.py", line 235, in execute
    return self._record(super().execute, sql, params)
           ^^^^^^^^^^^^^^^^^^^^^^^^^^^^^^^^^^^^^^^^^^
  File "/Users/moskvinangarkhaev/PycharmProjects/python_django/venv/lib/python3.11/site-packages/debug_toolbar/panels/sql/tracking.py", line 160, in _record
    return method(sql, params)
           ^^^^^^^^^^^^^^^^^^^
  File "/Users/moskvinangarkhaev/PycharmProjects/python_django/venv/lib/python3.11/site-packages/django/db/backends/utils.py", line 122, in execute
    return super().execute(sql, params)
           ^^^^^^^^^^^^^^^^^^^^^^^^^^^^
  File "/Users/moskvinangarkhaev/PycharmProjects/python_django/venv/lib/python3.11/site-packages/django/db/backends/utils.py", line 79, in execute
    return self._execute_with_wrappers(
           ^^^^^^^^^^^^^^^^^^^^^^^^^^^^
  File "/Users/moskvinangarkhaev/PycharmProjects/python_django/venv/lib/python3.11/site-packages/django/db/backends/utils.py", line 92, in _execute_with_wrappers
    return executor(sql, params, many, context)
           ^^^^^^^^^^^^^^^^^^^^^^^^^^^^^^^^^^^^
  File "/Users/moskvinangarkhaev/PycharmProjects/python_django/venv/lib/python3.11/site-packages/django/db/backends/utils.py", line 100, in _execute
    with self.db.wrap_database_errors:
  File "/Users/moskvinangarkhaev/PycharmProjects/python_django/venv/lib/python3.11/site-packages/django/db/utils.py", line 91, in __exit__
    raise dj_exc_value.with_traceback(traceback) from exc_value
  File "/Users/moskvinangarkhaev/PycharmProjects/python_django/venv/lib/python3.11/site-packages/django/db/backends/utils.py", line 105, in _execute
    return self.cursor.execute(sql, params)
           ^^^^^^^^^^^^^^^^^^^^^^^^^^^^^^^^
  File "/Users/moskvinangarkhaev/PycharmProjects/python_django/venv/lib/python3.11/site-packages/django/db/backends/sqlite3/base.py", line 329, in execute
    return super().execute(query, params)
           ^^^^^^^^^^^^^^^^^^^^^^^^^^^^^^
django.db.utils.IntegrityError: UNIQUE constraint failed: shopapp_order.id
2024-07-08 19:19:41,170 | INFO | django.utils.autoreload | /Users/moskvinangarkhaev/PycharmProjects/python_django/mysite/shopapp/admin.py changed, reloading.
2024-07-08 19:19:41,599 | INFO | django.utils.autoreload | Watching for file changes with StatReloader
2024-07-08 19:21:33,411 | ERROR | django.request | Internal Server Error: /admin/shopapp/order/import-order-csv/
Traceback (most recent call last):
  File "/Users/moskvinangarkhaev/PycharmProjects/python_django/venv/lib/python3.11/site-packages/django/core/handlers/exception.py", line 55, in inner
    response = get_response(request)
               ^^^^^^^^^^^^^^^^^^^^^
  File "/Users/moskvinangarkhaev/PycharmProjects/python_django/venv/lib/python3.11/site-packages/django/core/handlers/base.py", line 197, in _get_response
    response = wrapped_callback(request, *callback_args, **callback_kwargs)
               ^^^^^^^^^^^^^^^^^^^^^^^^^^^^^^^^^^^^^^^^^^^^^^^^^^^^^^^^^^^^
  File "/Users/moskvinangarkhaev/PycharmProjects/python_django/mysite/shopapp/admin.py", line 128, in import_csv
    order.products.set(products)
    ^^^^^^^^^^^^^^
  File "/Users/moskvinangarkhaev/PycharmProjects/python_django/venv/lib/python3.11/site-packages/django/db/models/fields/related_descriptors.py", line 650, in __get__
    return self.related_manager_cls(instance)
           ^^^^^^^^^^^^^^^^^^^^^^^^^^^^^^^^^^
  File "/Users/moskvinangarkhaev/PycharmProjects/python_django/venv/lib/python3.11/site-packages/django/db/models/fields/related_descriptors.py", line 1069, in __init__
    raise ValueError(
ValueError: "<Order: Order object (None)>" needs to have a value for field "id" before this many-to-many relationship can be used.
2024-07-08 19:22:57,458 | INFO | django.utils.autoreload | /Users/moskvinangarkhaev/PycharmProjects/python_django/mysite/shopapp/admin.py changed, reloading.
2024-07-08 19:22:58,039 | INFO | django.utils.autoreload | Watching for file changes with StatReloader
2024-07-08 19:27:39,488 | INFO | django.utils.autoreload | /Users/moskvinangarkhaev/PycharmProjects/python_django/mysite/shopapp/admin.py changed, reloading.
2024-07-08 19:27:39,914 | INFO | django.utils.autoreload | Watching for file changes with StatReloader
2024-07-10 13:15:58,635 | INFO | django.utils.autoreload | Watching for file changes with StatReloader
2024-07-10 13:16:00,218 | WARNING | django.request | Not Found: /
2024-07-22 17:05:14,866 | INFO | django.utils.autoreload | Watching for file changes with StatReloader
2024-07-22 17:05:21,982 | WARNING | django.request | Not Found: /
2024-07-22 17:05:30,708 | WARNING | django.request | Not Found: /orders
2024-07-22 17:15:48,999 | INFO | django.utils.autoreload | /Users/moskvinangarkhaev/PycharmProjects/python_django/mysite/shopapp/views.py changed, reloading.
2024-07-22 17:15:49,404 | INFO | django.utils.autoreload | Watching for file changes with StatReloader
2024-07-22 17:16:03,032 | INFO | django.utils.autoreload | /Users/moskvinangarkhaev/PycharmProjects/python_django/mysite/shopapp/views.py changed, reloading.
2024-07-22 17:16:03,383 | INFO | django.utils.autoreload | Watching for file changes with StatReloader
2024-07-22 17:17:31,853 | INFO | django.utils.autoreload | /Users/moskvinangarkhaev/PycharmProjects/python_django/mysite/shopapp/urls.py changed, reloading.
2024-07-22 17:17:32,219 | INFO | django.utils.autoreload | Watching for file changes with StatReloader
2024-07-22 17:18:01,516 | INFO | django.utils.autoreload | /Users/moskvinangarkhaev/PycharmProjects/python_django/mysite/shopapp/urls.py changed, reloading.
2024-07-22 17:18:01,882 | INFO | django.utils.autoreload | Watching for file changes with StatReloader
2024-07-22 17:18:34,174 | INFO | django.utils.autoreload | /Users/moskvinangarkhaev/PycharmProjects/python_django/mysite/shopapp/urls.py changed, reloading.
2024-07-22 17:18:34,570 | INFO | django.utils.autoreload | Watching for file changes with StatReloader
2024-07-22 17:19:10,929 | INFO | django.utils.autoreload | /Users/moskvinangarkhaev/PycharmProjects/python_django/mysite/shopapp/urls.py changed, reloading.
2024-07-22 17:19:11,358 | INFO | django.utils.autoreload | Watching for file changes with StatReloader
2024-07-22 17:21:25,447 | INFO | django.utils.autoreload | /Users/moskvinangarkhaev/PycharmProjects/python_django/mysite/shopapp/urls.py changed, reloading.
2024-07-22 17:21:25,932 | INFO | django.utils.autoreload | Watching for file changes with StatReloader
2024-07-22 17:26:00,116 | INFO | django.utils.autoreload | /Users/moskvinangarkhaev/PycharmProjects/python_django/mysite/shopapp/views.py changed, reloading.
2024-07-22 17:26:00,528 | INFO | django.utils.autoreload | Watching for file changes with StatReloader
2024-07-22 17:29:37,158 | INFO | django.utils.autoreload | /Users/moskvinangarkhaev/PycharmProjects/python_django/mysite/shopapp/views.py changed, reloading.
2024-07-22 17:29:37,681 | INFO | django.utils.autoreload | Watching for file changes with StatReloader
2024-07-22 17:29:58,606 | INFO | django.utils.autoreload | /Users/moskvinangarkhaev/PycharmProjects/python_django/mysite/shopapp/views.py changed, reloading.
2024-07-22 17:29:58,983 | INFO | django.utils.autoreload | Watching for file changes with StatReloader
2024-07-22 17:30:39,710 | INFO | django.utils.autoreload | /Users/moskvinangarkhaev/PycharmProjects/python_django/mysite/shopapp/views.py changed, reloading.
2024-07-22 17:30:40,135 | INFO | django.utils.autoreload | Watching for file changes with StatReloader
2024-07-22 17:33:24,257 | INFO | django.utils.autoreload | /Users/moskvinangarkhaev/PycharmProjects/python_django/mysite/shopapp/views.py changed, reloading.
2024-07-22 17:33:24,760 | INFO | django.utils.autoreload | Watching for file changes with StatReloader
2024-07-22 17:35:02,688 | INFO | django.utils.autoreload | /Users/moskvinangarkhaev/PycharmProjects/python_django/mysite/shopapp/views.py changed, reloading.
2024-07-22 17:35:03,081 | INFO | django.utils.autoreload | Watching for file changes with StatReloader
2024-07-22 17:36:09,749 | INFO | django.utils.autoreload | /Users/moskvinangarkhaev/PycharmProjects/python_django/mysite/shopapp/views.py changed, reloading.
2024-07-22 17:36:10,281 | INFO | django.utils.autoreload | Watching for file changes with StatReloader
2024-07-22 17:36:24,922 | INFO | django.utils.autoreload | /Users/moskvinangarkhaev/PycharmProjects/python_django/mysite/shopapp/views.py changed, reloading.
2024-07-22 17:36:25,276 | INFO | django.utils.autoreload | Watching for file changes with StatReloader
2024-07-22 17:37:02,606 | INFO | django.utils.autoreload | /Users/moskvinangarkhaev/PycharmProjects/python_django/mysite/shopapp/views.py changed, reloading.
2024-07-22 17:37:03,040 | INFO | django.utils.autoreload | Watching for file changes with StatReloader
2024-07-22 17:37:20,796 | INFO | django.utils.autoreload | /Users/moskvinangarkhaev/PycharmProjects/python_django/mysite/shopapp/views.py changed, reloading.
2024-07-22 17:37:21,226 | INFO | django.utils.autoreload | Watching for file changes with StatReloader
2024-07-22 17:37:58,779 | INFO | django.utils.autoreload | /Users/moskvinangarkhaev/PycharmProjects/python_django/mysite/shopapp/views.py changed, reloading.
2024-07-22 17:37:59,337 | INFO | django.utils.autoreload | Watching for file changes with StatReloader
2024-07-22 17:38:18,142 | INFO | django.utils.autoreload | /Users/moskvinangarkhaev/PycharmProjects/python_django/mysite/shopapp/views.py changed, reloading.
2024-07-22 17:38:18,696 | INFO | django.utils.autoreload | Watching for file changes with StatReloader
2024-07-22 17:38:41,654 | INFO | django.utils.autoreload | /Users/moskvinangarkhaev/PycharmProjects/python_django/mysite/shopapp/views.py changed, reloading.
2024-07-22 17:38:42,086 | INFO | django.utils.autoreload | Watching for file changes with StatReloader
2024-07-22 17:39:07,042 | INFO | django.utils.autoreload | /Users/moskvinangarkhaev/PycharmProjects/python_django/mysite/shopapp/views.py changed, reloading.
2024-07-22 17:39:07,409 | INFO | django.utils.autoreload | Watching for file changes with StatReloader
2024-07-22 17:39:33,352 | INFO | django.utils.autoreload | /Users/moskvinangarkhaev/PycharmProjects/python_django/mysite/shopapp/views.py changed, reloading.
2024-07-22 17:39:33,759 | INFO | django.utils.autoreload | Watching for file changes with StatReloader
2024-07-22 17:40:59,965 | INFO | django.utils.autoreload | /Users/moskvinangarkhaev/PycharmProjects/python_django/mysite/shopapp/views.py changed, reloading.
2024-07-22 17:41:00,331 | INFO | django.utils.autoreload | Watching for file changes with StatReloader
2024-07-22 17:42:04,795 | INFO | django.utils.autoreload | /Users/moskvinangarkhaev/PycharmProjects/python_django/mysite/shopapp/views.py changed, reloading.
2024-07-22 17:42:05,175 | INFO | django.utils.autoreload | Watching for file changes with StatReloader
2024-07-22 17:42:12,530 | INFO | django.utils.autoreload | /Users/moskvinangarkhaev/PycharmProjects/python_django/mysite/shopapp/views.py changed, reloading.
2024-07-22 17:42:12,883 | INFO | django.utils.autoreload | Watching for file changes with StatReloader
2024-07-22 17:42:36,770 | INFO | django.utils.autoreload | /Users/moskvinangarkhaev/PycharmProjects/python_django/mysite/shopapp/views.py changed, reloading.
2024-07-22 17:42:37,186 | INFO | django.utils.autoreload | Watching for file changes with StatReloader
2024-07-22 17:42:58,038 | INFO | django.utils.autoreload | /Users/moskvinangarkhaev/PycharmProjects/python_django/mysite/shopapp/views.py changed, reloading.
2024-07-22 17:42:58,410 | INFO | django.utils.autoreload | Watching for file changes with StatReloader
2024-07-22 17:44:01,931 | INFO | django.utils.autoreload | /Users/moskvinangarkhaev/PycharmProjects/python_django/mysite/shopapp/views.py changed, reloading.
2024-07-22 17:44:02,297 | INFO | django.utils.autoreload | Watching for file changes with StatReloader
2024-07-22 17:45:59,993 | INFO | django.utils.autoreload | /Users/moskvinangarkhaev/PycharmProjects/python_django/mysite/shopapp/views.py changed, reloading.
2024-07-22 17:46:00,395 | INFO | django.utils.autoreload | Watching for file changes with StatReloader
2024-07-22 17:53:01,253 | WARNING | django.request | Not Found: /ru/shop/1/orders/
2024-07-22 17:53:20,438 | WARNING | django.request | Not Found: /user/1/orders/
2024-07-22 17:53:36,730 | WARNING | django.request | Not Found: /shop/user/1/orders/
2024-07-22 17:54:01,802 | WARNING | django.request | Not Found: /shop/user/1/orders/
2024-07-22 17:54:23,817 | ERROR | django.request | Internal Server Error: /ru/shop/users/1/orders/
Traceback (most recent call last):
  File "/Users/moskvinangarkhaev/PycharmProjects/python_django/venv/lib/python3.11/site-packages/django/core/handlers/exception.py", line 55, in inner
    response = get_response(request)
               ^^^^^^^^^^^^^^^^^^^^^
  File "/Users/moskvinangarkhaev/PycharmProjects/python_django/venv/lib/python3.11/site-packages/django/core/handlers/base.py", line 197, in _get_response
    response = wrapped_callback(request, *callback_args, **callback_kwargs)
               ^^^^^^^^^^^^^^^^^^^^^^^^^^^^^^^^^^^^^^^^^^^^^^^^^^^^^^^^^^^^
  File "/Users/moskvinangarkhaev/PycharmProjects/python_django/venv/lib/python3.11/site-packages/django/views/generic/base.py", line 104, in view
    return self.dispatch(request, *args, **kwargs)
           ^^^^^^^^^^^^^^^^^^^^^^^^^^^^^^^^^^^^^^^
  File "/Users/moskvinangarkhaev/PycharmProjects/python_django/venv/lib/python3.11/site-packages/django/contrib/auth/mixins.py", line 132, in dispatch
    user_test_result = self.get_test_func()()
                       ^^^^^^^^^^^^^^^^^^^^^^
  File "/Users/moskvinangarkhaev/PycharmProjects/python_django/venv/lib/python3.11/site-packages/django/contrib/auth/mixins.py", line 119, in test_func
    raise NotImplementedError(
NotImplementedError: UserOrdersListView is missing the implementation of the test_func() method.
2024-07-22 17:55:17,969 | INFO | django.utils.autoreload | /Users/moskvinangarkhaev/PycharmProjects/python_django/mysite/shopapp/views.py changed, reloading.
2024-07-22 17:55:18,390 | INFO | django.utils.autoreload | Watching for file changes with StatReloader
2024-07-22 17:56:19,238 | WARNING | django.request | Not Found: /ru/myauth/about-me/2
2024-07-22 17:59:55,453 | INFO | django.utils.autoreload | /Users/moskvinangarkhaev/PycharmProjects/python_django/mysite/shopapp/views.py changed, reloading.
2024-07-22 17:59:56,002 | INFO | django.utils.autoreload | Watching for file changes with StatReloader
2024-07-22 18:01:57,654 | INFO | django.utils.autoreload | /Users/moskvinangarkhaev/PycharmProjects/python_django/mysite/shopapp/views.py changed, reloading.
2024-07-22 18:01:58,160 | INFO | django.utils.autoreload | Watching for file changes with StatReloader
2024-07-22 18:02:14,112 | ERROR | django.request | Internal Server Error: /ru/shop/users/1/orders/
Traceback (most recent call last):
  File "/Users/moskvinangarkhaev/PycharmProjects/python_django/venv/lib/python3.11/site-packages/django/core/handlers/exception.py", line 55, in inner
    response = get_response(request)
               ^^^^^^^^^^^^^^^^^^^^^
  File "/Users/moskvinangarkhaev/PycharmProjects/python_django/venv/lib/python3.11/site-packages/django/core/handlers/base.py", line 197, in _get_response
    response = wrapped_callback(request, *callback_args, **callback_kwargs)
               ^^^^^^^^^^^^^^^^^^^^^^^^^^^^^^^^^^^^^^^^^^^^^^^^^^^^^^^^^^^^
  File "/Users/moskvinangarkhaev/PycharmProjects/python_django/venv/lib/python3.11/site-packages/django/views/generic/base.py", line 104, in view
    return self.dispatch(request, *args, **kwargs)
           ^^^^^^^^^^^^^^^^^^^^^^^^^^^^^^^^^^^^^^^
  File "/Users/moskvinangarkhaev/PycharmProjects/python_django/venv/lib/python3.11/site-packages/django/contrib/auth/mixins.py", line 132, in dispatch
    user_test_result = self.get_test_func()()
                       ^^^^^^^^^^^^^^^^^^^^^^
  File "/Users/moskvinangarkhaev/PycharmProjects/python_django/mysite/shopapp/views.py", line 202, in test_func
    return self.request.user.is_superuser or self.request.user == self.owner
                                                                  ^^^^^^^^^^
AttributeError: 'UserOrdersListView' object has no attribute 'owner'
2024-07-22 18:02:18,840 | ERROR | django.request | Internal Server Error: /ru/shop/users/2/orders/
Traceback (most recent call last):
  File "/Users/moskvinangarkhaev/PycharmProjects/python_django/venv/lib/python3.11/site-packages/django/core/handlers/exception.py", line 55, in inner
    response = get_response(request)
               ^^^^^^^^^^^^^^^^^^^^^
  File "/Users/moskvinangarkhaev/PycharmProjects/python_django/venv/lib/python3.11/site-packages/django/core/handlers/base.py", line 197, in _get_response
    response = wrapped_callback(request, *callback_args, **callback_kwargs)
               ^^^^^^^^^^^^^^^^^^^^^^^^^^^^^^^^^^^^^^^^^^^^^^^^^^^^^^^^^^^^
  File "/Users/moskvinangarkhaev/PycharmProjects/python_django/venv/lib/python3.11/site-packages/django/views/generic/base.py", line 104, in view
    return self.dispatch(request, *args, **kwargs)
           ^^^^^^^^^^^^^^^^^^^^^^^^^^^^^^^^^^^^^^^
  File "/Users/moskvinangarkhaev/PycharmProjects/python_django/venv/lib/python3.11/site-packages/django/contrib/auth/mixins.py", line 132, in dispatch
    user_test_result = self.get_test_func()()
                       ^^^^^^^^^^^^^^^^^^^^^^
  File "/Users/moskvinangarkhaev/PycharmProjects/python_django/mysite/shopapp/views.py", line 202, in test_func
    return self.request.user.is_superuser or self.request.user == self.owner
                                                                  ^^^^^^^^^^
AttributeError: 'UserOrdersListView' object has no attribute 'owner'
2024-07-22 18:02:43,084 | INFO | django.utils.autoreload | /Users/moskvinangarkhaev/PycharmProjects/python_django/mysite/shopapp/views.py changed, reloading.
2024-07-22 18:02:43,468 | INFO | django.utils.autoreload | Watching for file changes with StatReloader
2024-07-22 18:02:48,213 | WARNING | django.request | Forbidden (Permission denied): /ru/shop/users/1/orders/
Traceback (most recent call last):
  File "/Users/moskvinangarkhaev/PycharmProjects/python_django/venv/lib/python3.11/site-packages/django/core/handlers/exception.py", line 55, in inner
    response = get_response(request)
               ^^^^^^^^^^^^^^^^^^^^^
  File "/Users/moskvinangarkhaev/PycharmProjects/python_django/venv/lib/python3.11/site-packages/django/core/handlers/base.py", line 197, in _get_response
    response = wrapped_callback(request, *callback_args, **callback_kwargs)
               ^^^^^^^^^^^^^^^^^^^^^^^^^^^^^^^^^^^^^^^^^^^^^^^^^^^^^^^^^^^^
  File "/Users/moskvinangarkhaev/PycharmProjects/python_django/venv/lib/python3.11/site-packages/django/views/generic/base.py", line 104, in view
    return self.dispatch(request, *args, **kwargs)
           ^^^^^^^^^^^^^^^^^^^^^^^^^^^^^^^^^^^^^^^
  File "/Users/moskvinangarkhaev/PycharmProjects/python_django/venv/lib/python3.11/site-packages/django/contrib/auth/mixins.py", line 134, in dispatch
    return self.handle_no_permission()
           ^^^^^^^^^^^^^^^^^^^^^^^^^^^
  File "/Users/moskvinangarkhaev/PycharmProjects/python_django/venv/lib/python3.11/site-packages/django/contrib/auth/mixins.py", line 48, in handle_no_permission
    raise PermissionDenied(self.get_permission_denied_message())
django.core.exceptions.PermissionDenied
2024-07-22 18:03:49,179 | WARNING | django.request | Forbidden (Permission denied): /ru/shop/users/2/orders/
Traceback (most recent call last):
  File "/Users/moskvinangarkhaev/PycharmProjects/python_django/venv/lib/python3.11/site-packages/django/core/handlers/exception.py", line 55, in inner
    response = get_response(request)
               ^^^^^^^^^^^^^^^^^^^^^
  File "/Users/moskvinangarkhaev/PycharmProjects/python_django/venv/lib/python3.11/site-packages/django/core/handlers/base.py", line 197, in _get_response
    response = wrapped_callback(request, *callback_args, **callback_kwargs)
               ^^^^^^^^^^^^^^^^^^^^^^^^^^^^^^^^^^^^^^^^^^^^^^^^^^^^^^^^^^^^
  File "/Users/moskvinangarkhaev/PycharmProjects/python_django/venv/lib/python3.11/site-packages/django/views/generic/base.py", line 104, in view
    return self.dispatch(request, *args, **kwargs)
           ^^^^^^^^^^^^^^^^^^^^^^^^^^^^^^^^^^^^^^^
  File "/Users/moskvinangarkhaev/PycharmProjects/python_django/venv/lib/python3.11/site-packages/django/contrib/auth/mixins.py", line 134, in dispatch
    return self.handle_no_permission()
           ^^^^^^^^^^^^^^^^^^^^^^^^^^^
  File "/Users/moskvinangarkhaev/PycharmProjects/python_django/venv/lib/python3.11/site-packages/django/contrib/auth/mixins.py", line 48, in handle_no_permission
    raise PermissionDenied(self.get_permission_denied_message())
django.core.exceptions.PermissionDenied
2024-07-22 18:04:06,922 | WARNING | django.request | Forbidden (Permission denied): /ru/shop/orders/
Traceback (most recent call last):
  File "/Users/moskvinangarkhaev/PycharmProjects/python_django/venv/lib/python3.11/site-packages/django/core/handlers/exception.py", line 55, in inner
    response = get_response(request)
               ^^^^^^^^^^^^^^^^^^^^^
  File "/Users/moskvinangarkhaev/PycharmProjects/python_django/venv/lib/python3.11/site-packages/django/core/handlers/base.py", line 197, in _get_response
    response = wrapped_callback(request, *callback_args, **callback_kwargs)
               ^^^^^^^^^^^^^^^^^^^^^^^^^^^^^^^^^^^^^^^^^^^^^^^^^^^^^^^^^^^^
  File "/Users/moskvinangarkhaev/PycharmProjects/python_django/venv/lib/python3.11/site-packages/django/views/generic/base.py", line 104, in view
    return self.dispatch(request, *args, **kwargs)
           ^^^^^^^^^^^^^^^^^^^^^^^^^^^^^^^^^^^^^^^
  File "/Users/moskvinangarkhaev/PycharmProjects/python_django/venv/lib/python3.11/site-packages/django/contrib/auth/mixins.py", line 108, in dispatch
    return self.handle_no_permission()
           ^^^^^^^^^^^^^^^^^^^^^^^^^^^
  File "/Users/moskvinangarkhaev/PycharmProjects/python_django/venv/lib/python3.11/site-packages/django/contrib/auth/mixins.py", line 48, in handle_no_permission
    raise PermissionDenied(self.get_permission_denied_message())
django.core.exceptions.PermissionDenied
2024-07-22 18:04:42,171 | INFO | django.utils.autoreload | /Users/moskvinangarkhaev/PycharmProjects/python_django/mysite/shopapp/views.py changed, reloading.
2024-07-22 18:04:42,538 | INFO | django.utils.autoreload | Watching for file changes with StatReloader
2024-07-22 18:04:56,860 | WARNING | django.request | Forbidden (Permission denied): /ru/shop/users/2/orders/
Traceback (most recent call last):
  File "/Users/moskvinangarkhaev/PycharmProjects/python_django/venv/lib/python3.11/site-packages/django/core/handlers/exception.py", line 55, in inner
    response = get_response(request)
               ^^^^^^^^^^^^^^^^^^^^^
  File "/Users/moskvinangarkhaev/PycharmProjects/python_django/venv/lib/python3.11/site-packages/django/core/handlers/base.py", line 197, in _get_response
    response = wrapped_callback(request, *callback_args, **callback_kwargs)
               ^^^^^^^^^^^^^^^^^^^^^^^^^^^^^^^^^^^^^^^^^^^^^^^^^^^^^^^^^^^^
  File "/Users/moskvinangarkhaev/PycharmProjects/python_django/venv/lib/python3.11/site-packages/django/views/generic/base.py", line 104, in view
    return self.dispatch(request, *args, **kwargs)
           ^^^^^^^^^^^^^^^^^^^^^^^^^^^^^^^^^^^^^^^
  File "/Users/moskvinangarkhaev/PycharmProjects/python_django/venv/lib/python3.11/site-packages/django/contrib/auth/mixins.py", line 134, in dispatch
    return self.handle_no_permission()
           ^^^^^^^^^^^^^^^^^^^^^^^^^^^
  File "/Users/moskvinangarkhaev/PycharmProjects/python_django/venv/lib/python3.11/site-packages/django/contrib/auth/mixins.py", line 48, in handle_no_permission
    raise PermissionDenied(self.get_permission_denied_message())
django.core.exceptions.PermissionDenied
2024-07-22 18:31:33,666 | WARNING | django.request | Forbidden (Permission denied): /ru/shop/orders/
Traceback (most recent call last):
  File "/Users/moskvinangarkhaev/PycharmProjects/python_django/venv/lib/python3.11/site-packages/django/core/handlers/exception.py", line 55, in inner
    response = get_response(request)
               ^^^^^^^^^^^^^^^^^^^^^
  File "/Users/moskvinangarkhaev/PycharmProjects/python_django/venv/lib/python3.11/site-packages/django/core/handlers/base.py", line 197, in _get_response
    response = wrapped_callback(request, *callback_args, **callback_kwargs)
               ^^^^^^^^^^^^^^^^^^^^^^^^^^^^^^^^^^^^^^^^^^^^^^^^^^^^^^^^^^^^
  File "/Users/moskvinangarkhaev/PycharmProjects/python_django/venv/lib/python3.11/site-packages/django/views/generic/base.py", line 104, in view
    return self.dispatch(request, *args, **kwargs)
           ^^^^^^^^^^^^^^^^^^^^^^^^^^^^^^^^^^^^^^^
  File "/Users/moskvinangarkhaev/PycharmProjects/python_django/venv/lib/python3.11/site-packages/django/contrib/auth/mixins.py", line 108, in dispatch
    return self.handle_no_permission()
           ^^^^^^^^^^^^^^^^^^^^^^^^^^^
  File "/Users/moskvinangarkhaev/PycharmProjects/python_django/venv/lib/python3.11/site-packages/django/contrib/auth/mixins.py", line 48, in handle_no_permission
    raise PermissionDenied(self.get_permission_denied_message())
django.core.exceptions.PermissionDenied
2024-07-22 18:32:17,482 | WARNING | django.request | Forbidden (Permission denied): /ru/shop/orders/
Traceback (most recent call last):
  File "/Users/moskvinangarkhaev/PycharmProjects/python_django/venv/lib/python3.11/site-packages/django/core/handlers/exception.py", line 55, in inner
    response = get_response(request)
               ^^^^^^^^^^^^^^^^^^^^^
  File "/Users/moskvinangarkhaev/PycharmProjects/python_django/venv/lib/python3.11/site-packages/django/core/handlers/base.py", line 197, in _get_response
    response = wrapped_callback(request, *callback_args, **callback_kwargs)
               ^^^^^^^^^^^^^^^^^^^^^^^^^^^^^^^^^^^^^^^^^^^^^^^^^^^^^^^^^^^^
  File "/Users/moskvinangarkhaev/PycharmProjects/python_django/venv/lib/python3.11/site-packages/django/views/generic/base.py", line 104, in view
    return self.dispatch(request, *args, **kwargs)
           ^^^^^^^^^^^^^^^^^^^^^^^^^^^^^^^^^^^^^^^
  File "/Users/moskvinangarkhaev/PycharmProjects/python_django/venv/lib/python3.11/site-packages/django/contrib/auth/mixins.py", line 108, in dispatch
    return self.handle_no_permission()
           ^^^^^^^^^^^^^^^^^^^^^^^^^^^
  File "/Users/moskvinangarkhaev/PycharmProjects/python_django/venv/lib/python3.11/site-packages/django/contrib/auth/mixins.py", line 48, in handle_no_permission
    raise PermissionDenied(self.get_permission_denied_message())
django.core.exceptions.PermissionDenied
2024-07-22 18:32:46,603 | INFO | django.utils.autoreload | /Users/moskvinangarkhaev/PycharmProjects/python_django/mysite/shopapp/views.py changed, reloading.
2024-07-22 18:32:47,018 | INFO | django.utils.autoreload | Watching for file changes with StatReloader
2024-07-22 18:33:06,321 | ERROR | django.request | Internal Server Error: /ru/shop/orders/create
Traceback (most recent call last):
  File "/Users/moskvinangarkhaev/PycharmProjects/python_django/venv/lib/python3.11/site-packages/django/core/handlers/exception.py", line 55, in inner
    response = get_response(request)
               ^^^^^^^^^^^^^^^^^^^^^
  File "/Users/moskvinangarkhaev/PycharmProjects/python_django/venv/lib/python3.11/site-packages/django/core/handlers/base.py", line 197, in _get_response
    response = wrapped_callback(request, *callback_args, **callback_kwargs)
               ^^^^^^^^^^^^^^^^^^^^^^^^^^^^^^^^^^^^^^^^^^^^^^^^^^^^^^^^^^^^
  File "/Users/moskvinangarkhaev/PycharmProjects/python_django/venv/lib/python3.11/site-packages/django/views/generic/base.py", line 104, in view
    return self.dispatch(request, *args, **kwargs)
           ^^^^^^^^^^^^^^^^^^^^^^^^^^^^^^^^^^^^^^^
  File "/Users/moskvinangarkhaev/PycharmProjects/python_django/venv/lib/python3.11/site-packages/django/contrib/auth/mixins.py", line 73, in dispatch
    return super().dispatch(request, *args, **kwargs)
           ^^^^^^^^^^^^^^^^^^^^^^^^^^^^^^^^^^^^^^^^^^
  File "/Users/moskvinangarkhaev/PycharmProjects/python_django/venv/lib/python3.11/site-packages/django/views/generic/base.py", line 143, in dispatch
    return handler(request, *args, **kwargs)
           ^^^^^^^^^^^^^^^^^^^^^^^^^^^^^^^^^
  File "/Users/moskvinangarkhaev/PycharmProjects/python_django/venv/lib/python3.11/site-packages/django/views/generic/edit.py", line 182, in post
    return super().post(request, *args, **kwargs)
           ^^^^^^^^^^^^^^^^^^^^^^^^^^^^^^^^^^^^^^
  File "/Users/moskvinangarkhaev/PycharmProjects/python_django/venv/lib/python3.11/site-packages/django/views/generic/edit.py", line 151, in post
    return self.form_valid(form)
           ^^^^^^^^^^^^^^^^^^^^^
  File "/Users/moskvinangarkhaev/PycharmProjects/python_django/venv/lib/python3.11/site-packages/django/views/generic/edit.py", line 134, in form_valid
    return super().form_valid(form)
           ^^^^^^^^^^^^^^^^^^^^^^^^
  File "/Users/moskvinangarkhaev/PycharmProjects/python_django/venv/lib/python3.11/site-packages/django/views/generic/edit.py", line 63, in form_valid
    return HttpResponseRedirect(self.get_success_url())
                                ^^^^^^^^^^^^^^^^^^^^^^
  File "/Users/moskvinangarkhaev/PycharmProjects/python_django/venv/lib/python3.11/site-packages/django/views/generic/edit.py", line 119, in get_success_url
    if self.success_url:
  File "/Users/moskvinangarkhaev/PycharmProjects/python_django/venv/lib/python3.11/site-packages/django/utils/functional.py", line 187, in __wrapper__
    result = func(*self._args, **self._kw)
             ^^^^^^^^^^^^^^^^^^^^^^^^^^^^^
  File "/Users/moskvinangarkhaev/PycharmProjects/python_django/venv/lib/python3.11/site-packages/django/urls/base.py", line 88, in reverse
    return resolver._reverse_with_prefix(view, prefix, *args, **kwargs)
           ^^^^^^^^^^^^^^^^^^^^^^^^^^^^^^^^^^^^^^^^^^^^^^^^^^^^^^^^^^^^
  File "/Users/moskvinangarkhaev/PycharmProjects/python_django/venv/lib/python3.11/site-packages/django/urls/resolvers.py", line 851, in _reverse_with_prefix
    raise NoReverseMatch(msg)
django.urls.exceptions.NoReverseMatch: Reverse for 'user_orders_list' with no arguments not found. 1 pattern(s) tried: ['ru/shop/users/(?P<user_id>[0-9]+)/orders/\\Z']
2024-07-22 18:33:23,066 | ERROR | django.request | Internal Server Error: /ru/shop/orders/create
Traceback (most recent call last):
  File "/Users/moskvinangarkhaev/PycharmProjects/python_django/venv/lib/python3.11/site-packages/django/core/handlers/exception.py", line 55, in inner
    response = get_response(request)
               ^^^^^^^^^^^^^^^^^^^^^
  File "/Users/moskvinangarkhaev/PycharmProjects/python_django/venv/lib/python3.11/site-packages/django/core/handlers/base.py", line 197, in _get_response
    response = wrapped_callback(request, *callback_args, **callback_kwargs)
               ^^^^^^^^^^^^^^^^^^^^^^^^^^^^^^^^^^^^^^^^^^^^^^^^^^^^^^^^^^^^
  File "/Users/moskvinangarkhaev/PycharmProjects/python_django/venv/lib/python3.11/site-packages/django/views/generic/base.py", line 104, in view
    return self.dispatch(request, *args, **kwargs)
           ^^^^^^^^^^^^^^^^^^^^^^^^^^^^^^^^^^^^^^^
  File "/Users/moskvinangarkhaev/PycharmProjects/python_django/venv/lib/python3.11/site-packages/django/contrib/auth/mixins.py", line 73, in dispatch
    return super().dispatch(request, *args, **kwargs)
           ^^^^^^^^^^^^^^^^^^^^^^^^^^^^^^^^^^^^^^^^^^
  File "/Users/moskvinangarkhaev/PycharmProjects/python_django/venv/lib/python3.11/site-packages/django/views/generic/base.py", line 143, in dispatch
    return handler(request, *args, **kwargs)
           ^^^^^^^^^^^^^^^^^^^^^^^^^^^^^^^^^
  File "/Users/moskvinangarkhaev/PycharmProjects/python_django/venv/lib/python3.11/site-packages/django/views/generic/edit.py", line 182, in post
    return super().post(request, *args, **kwargs)
           ^^^^^^^^^^^^^^^^^^^^^^^^^^^^^^^^^^^^^^
  File "/Users/moskvinangarkhaev/PycharmProjects/python_django/venv/lib/python3.11/site-packages/django/views/generic/edit.py", line 151, in post
    return self.form_valid(form)
           ^^^^^^^^^^^^^^^^^^^^^
  File "/Users/moskvinangarkhaev/PycharmProjects/python_django/venv/lib/python3.11/site-packages/django/views/generic/edit.py", line 134, in form_valid
    return super().form_valid(form)
           ^^^^^^^^^^^^^^^^^^^^^^^^
  File "/Users/moskvinangarkhaev/PycharmProjects/python_django/venv/lib/python3.11/site-packages/django/views/generic/edit.py", line 63, in form_valid
    return HttpResponseRedirect(self.get_success_url())
                                ^^^^^^^^^^^^^^^^^^^^^^
  File "/Users/moskvinangarkhaev/PycharmProjects/python_django/venv/lib/python3.11/site-packages/django/views/generic/edit.py", line 119, in get_success_url
    if self.success_url:
  File "/Users/moskvinangarkhaev/PycharmProjects/python_django/venv/lib/python3.11/site-packages/django/utils/functional.py", line 187, in __wrapper__
    result = func(*self._args, **self._kw)
             ^^^^^^^^^^^^^^^^^^^^^^^^^^^^^
  File "/Users/moskvinangarkhaev/PycharmProjects/python_django/venv/lib/python3.11/site-packages/django/urls/base.py", line 88, in reverse
    return resolver._reverse_with_prefix(view, prefix, *args, **kwargs)
           ^^^^^^^^^^^^^^^^^^^^^^^^^^^^^^^^^^^^^^^^^^^^^^^^^^^^^^^^^^^^
  File "/Users/moskvinangarkhaev/PycharmProjects/python_django/venv/lib/python3.11/site-packages/django/urls/resolvers.py", line 851, in _reverse_with_prefix
    raise NoReverseMatch(msg)
django.urls.exceptions.NoReverseMatch: Reverse for 'user_orders_list' with no arguments not found. 1 pattern(s) tried: ['ru/shop/users/(?P<user_id>[0-9]+)/orders/\\Z']
2024-07-22 18:33:37,665 | ERROR | django.request | Internal Server Error: /ru/shop/order/12/delete
Traceback (most recent call last):
  File "/Users/moskvinangarkhaev/PycharmProjects/python_django/venv/lib/python3.11/site-packages/django/core/handlers/exception.py", line 55, in inner
    response = get_response(request)
               ^^^^^^^^^^^^^^^^^^^^^
  File "/Users/moskvinangarkhaev/PycharmProjects/python_django/venv/lib/python3.11/site-packages/django/core/handlers/base.py", line 197, in _get_response
    response = wrapped_callback(request, *callback_args, **callback_kwargs)
               ^^^^^^^^^^^^^^^^^^^^^^^^^^^^^^^^^^^^^^^^^^^^^^^^^^^^^^^^^^^^
  File "/Users/moskvinangarkhaev/PycharmProjects/python_django/venv/lib/python3.11/site-packages/django/views/generic/base.py", line 104, in view
    return self.dispatch(request, *args, **kwargs)
           ^^^^^^^^^^^^^^^^^^^^^^^^^^^^^^^^^^^^^^^
  File "/Users/moskvinangarkhaev/PycharmProjects/python_django/venv/lib/python3.11/site-packages/django/contrib/auth/mixins.py", line 135, in dispatch
    return super().dispatch(request, *args, **kwargs)
           ^^^^^^^^^^^^^^^^^^^^^^^^^^^^^^^^^^^^^^^^^^
  File "/Users/moskvinangarkhaev/PycharmProjects/python_django/venv/lib/python3.11/site-packages/django/views/generic/base.py", line 143, in dispatch
    return handler(request, *args, **kwargs)
           ^^^^^^^^^^^^^^^^^^^^^^^^^^^^^^^^^
  File "/Users/moskvinangarkhaev/PycharmProjects/python_django/venv/lib/python3.11/site-packages/django/views/generic/edit.py", line 258, in post
    return self.form_valid(form)
           ^^^^^^^^^^^^^^^^^^^^^
  File "/Users/moskvinangarkhaev/PycharmProjects/python_django/venv/lib/python3.11/site-packages/django/views/generic/edit.py", line 263, in form_valid
    success_url = self.get_success_url()
                  ^^^^^^^^^^^^^^^^^^^^^^
  File "/Users/moskvinangarkhaev/PycharmProjects/python_django/venv/lib/python3.11/site-packages/django/views/generic/edit.py", line 235, in get_success_url
    if self.success_url:
  File "/Users/moskvinangarkhaev/PycharmProjects/python_django/venv/lib/python3.11/site-packages/django/utils/functional.py", line 187, in __wrapper__
    result = func(*self._args, **self._kw)
             ^^^^^^^^^^^^^^^^^^^^^^^^^^^^^
  File "/Users/moskvinangarkhaev/PycharmProjects/python_django/venv/lib/python3.11/site-packages/django/urls/base.py", line 88, in reverse
    return resolver._reverse_with_prefix(view, prefix, *args, **kwargs)
           ^^^^^^^^^^^^^^^^^^^^^^^^^^^^^^^^^^^^^^^^^^^^^^^^^^^^^^^^^^^^
  File "/Users/moskvinangarkhaev/PycharmProjects/python_django/venv/lib/python3.11/site-packages/django/urls/resolvers.py", line 851, in _reverse_with_prefix
    raise NoReverseMatch(msg)
django.urls.exceptions.NoReverseMatch: Reverse for 'user_orders_list' with no arguments not found. 1 pattern(s) tried: ['ru/shop/users/(?P<user_id>[0-9]+)/orders/\\Z']
2024-07-22 18:35:46,999 | INFO | django.utils.autoreload | /Users/moskvinangarkhaev/PycharmProjects/python_django/mysite/shopapp/views.py changed, reloading.
2024-07-22 18:35:47,720 | INFO | django.utils.autoreload | Watching for file changes with StatReloader
2024-07-22 18:35:52,305 | WARNING | django.request | Forbidden (Permission denied): /ru/shop/orders/
Traceback (most recent call last):
  File "/Users/moskvinangarkhaev/PycharmProjects/python_django/venv/lib/python3.11/site-packages/django/core/handlers/exception.py", line 55, in inner
    response = get_response(request)
               ^^^^^^^^^^^^^^^^^^^^^
  File "/Users/moskvinangarkhaev/PycharmProjects/python_django/venv/lib/python3.11/site-packages/django/core/handlers/base.py", line 197, in _get_response
    response = wrapped_callback(request, *callback_args, **callback_kwargs)
               ^^^^^^^^^^^^^^^^^^^^^^^^^^^^^^^^^^^^^^^^^^^^^^^^^^^^^^^^^^^^
  File "/Users/moskvinangarkhaev/PycharmProjects/python_django/venv/lib/python3.11/site-packages/django/views/generic/base.py", line 104, in view
    return self.dispatch(request, *args, **kwargs)
           ^^^^^^^^^^^^^^^^^^^^^^^^^^^^^^^^^^^^^^^
  File "/Users/moskvinangarkhaev/PycharmProjects/python_django/venv/lib/python3.11/site-packages/django/contrib/auth/mixins.py", line 108, in dispatch
    return self.handle_no_permission()
           ^^^^^^^^^^^^^^^^^^^^^^^^^^^
  File "/Users/moskvinangarkhaev/PycharmProjects/python_django/venv/lib/python3.11/site-packages/django/contrib/auth/mixins.py", line 48, in handle_no_permission
    raise PermissionDenied(self.get_permission_denied_message())
django.core.exceptions.PermissionDenied
2024-07-22 18:37:33,433 | INFO | django.utils.autoreload | Watching for file changes with StatReloader
2024-07-22 18:38:44,086 | INFO | django.utils.autoreload | Watching for file changes with StatReloader
2024-07-22 18:39:00,619 | ERROR | django.request | Internal Server Error: /ru/shop/order/12
Traceback (most recent call last):
  File "/Users/moskvinangarkhaev/PycharmProjects/python_django/venv/lib/python3.11/site-packages/django/core/handlers/exception.py", line 55, in inner
    response = get_response(request)
               ^^^^^^^^^^^^^^^^^^^^^
  File "/Users/moskvinangarkhaev/PycharmProjects/python_django/venv/lib/python3.11/site-packages/django/core/handlers/base.py", line 220, in _get_response
    response = response.render()
               ^^^^^^^^^^^^^^^^^
  File "/Users/moskvinangarkhaev/PycharmProjects/python_django/venv/lib/python3.11/site-packages/django/template/response.py", line 114, in render
    self.content = self.rendered_content
                   ^^^^^^^^^^^^^^^^^^^^^
  File "/Users/moskvinangarkhaev/PycharmProjects/python_django/venv/lib/python3.11/site-packages/django/template/response.py", line 92, in rendered_content
    return template.render(context, self._request)
           ^^^^^^^^^^^^^^^^^^^^^^^^^^^^^^^^^^^^^^^
  File "/Users/moskvinangarkhaev/PycharmProjects/python_django/venv/lib/python3.11/site-packages/django/template/backends/django.py", line 61, in render
    return self.template.render(context)
           ^^^^^^^^^^^^^^^^^^^^^^^^^^^^^
  File "/Users/moskvinangarkhaev/PycharmProjects/python_django/venv/lib/python3.11/site-packages/django/template/base.py", line 171, in render
    return self._render(context)
           ^^^^^^^^^^^^^^^^^^^^^
  File "/Users/moskvinangarkhaev/PycharmProjects/python_django/venv/lib/python3.11/site-packages/django/test/utils.py", line 111, in instrumented_test_render
    return self.nodelist.render(context)
           ^^^^^^^^^^^^^^^^^^^^^^^^^^^^^
  File "/Users/moskvinangarkhaev/PycharmProjects/python_django/venv/lib/python3.11/site-packages/django/template/base.py", line 1000, in render
    return SafeString("".join([node.render_annotated(context) for node in self]))
                              ^^^^^^^^^^^^^^^^^^^^^^^^^^^^^^^^^^^^^^^^^^^^^^^^^
  File "/Users/moskvinangarkhaev/PycharmProjects/python_django/venv/lib/python3.11/site-packages/django/template/base.py", line 1000, in <listcomp>
    return SafeString("".join([node.render_annotated(context) for node in self]))
                               ^^^^^^^^^^^^^^^^^^^^^^^^^^^^^^
  File "/Users/moskvinangarkhaev/PycharmProjects/python_django/venv/lib/python3.11/site-packages/django/template/base.py", line 961, in render_annotated
    return self.render(context)
           ^^^^^^^^^^^^^^^^^^^^
  File "/Users/moskvinangarkhaev/PycharmProjects/python_django/venv/lib/python3.11/site-packages/django/template/loader_tags.py", line 159, in render
    return compiled_parent._render(context)
           ^^^^^^^^^^^^^^^^^^^^^^^^^^^^^^^^
  File "/Users/moskvinangarkhaev/PycharmProjects/python_django/venv/lib/python3.11/site-packages/django/test/utils.py", line 111, in instrumented_test_render
    return self.nodelist.render(context)
           ^^^^^^^^^^^^^^^^^^^^^^^^^^^^^
  File "/Users/moskvinangarkhaev/PycharmProjects/python_django/venv/lib/python3.11/site-packages/django/template/base.py", line 1000, in render
    return SafeString("".join([node.render_annotated(context) for node in self]))
                              ^^^^^^^^^^^^^^^^^^^^^^^^^^^^^^^^^^^^^^^^^^^^^^^^^
  File "/Users/moskvinangarkhaev/PycharmProjects/python_django/venv/lib/python3.11/site-packages/django/template/base.py", line 1000, in <listcomp>
    return SafeString("".join([node.render_annotated(context) for node in self]))
                               ^^^^^^^^^^^^^^^^^^^^^^^^^^^^^^
  File "/Users/moskvinangarkhaev/PycharmProjects/python_django/venv/lib/python3.11/site-packages/django/template/base.py", line 961, in render_annotated
    return self.render(context)
           ^^^^^^^^^^^^^^^^^^^^
  File "/Users/moskvinangarkhaev/PycharmProjects/python_django/venv/lib/python3.11/site-packages/django/template/loader_tags.py", line 65, in render
    result = block.nodelist.render(context)
             ^^^^^^^^^^^^^^^^^^^^^^^^^^^^^^
  File "/Users/moskvinangarkhaev/PycharmProjects/python_django/venv/lib/python3.11/site-packages/django/template/base.py", line 1000, in render
    return SafeString("".join([node.render_annotated(context) for node in self]))
                              ^^^^^^^^^^^^^^^^^^^^^^^^^^^^^^^^^^^^^^^^^^^^^^^^^
  File "/Users/moskvinangarkhaev/PycharmProjects/python_django/venv/lib/python3.11/site-packages/django/template/base.py", line 1000, in <listcomp>
    return SafeString("".join([node.render_annotated(context) for node in self]))
                               ^^^^^^^^^^^^^^^^^^^^^^^^^^^^^^
  File "/Users/moskvinangarkhaev/PycharmProjects/python_django/venv/lib/python3.11/site-packages/django/template/base.py", line 961, in render_annotated
    return self.render(context)
           ^^^^^^^^^^^^^^^^^^^^
  File "/Users/moskvinangarkhaev/PycharmProjects/python_django/venv/lib/python3.11/site-packages/django/template/defaulttags.py", line 479, in render
    url = reverse(view_name, args=args, kwargs=kwargs, current_app=current_app)
          ^^^^^^^^^^^^^^^^^^^^^^^^^^^^^^^^^^^^^^^^^^^^^^^^^^^^^^^^^^^^^^^^^^^^^
  File "/Users/moskvinangarkhaev/PycharmProjects/python_django/venv/lib/python3.11/site-packages/django/urls/base.py", line 88, in reverse
    return resolver._reverse_with_prefix(view, prefix, *args, **kwargs)
           ^^^^^^^^^^^^^^^^^^^^^^^^^^^^^^^^^^^^^^^^^^^^^^^^^^^^^^^^^^^^
  File "/Users/moskvinangarkhaev/PycharmProjects/python_django/venv/lib/python3.11/site-packages/django/urls/resolvers.py", line 851, in _reverse_with_prefix
    raise NoReverseMatch(msg)
django.urls.exceptions.NoReverseMatch: Reverse for 'user_orders_list' with keyword arguments '{'pk': 7}' not found. 1 pattern(s) tried: ['ru/shop/users/(?P<user_id>[0-9]+)/orders/\\Z']
2024-07-22 18:40:00,062 | ERROR | django.request | Internal Server Error: /ru/shop/order/12/delete
Traceback (most recent call last):
  File "/Users/moskvinangarkhaev/PycharmProjects/python_django/venv/lib/python3.11/site-packages/django/core/handlers/exception.py", line 55, in inner
    response = get_response(request)
               ^^^^^^^^^^^^^^^^^^^^^
  File "/Users/moskvinangarkhaev/PycharmProjects/python_django/venv/lib/python3.11/site-packages/django/core/handlers/base.py", line 197, in _get_response
    response = wrapped_callback(request, *callback_args, **callback_kwargs)
               ^^^^^^^^^^^^^^^^^^^^^^^^^^^^^^^^^^^^^^^^^^^^^^^^^^^^^^^^^^^^
  File "/Users/moskvinangarkhaev/PycharmProjects/python_django/venv/lib/python3.11/site-packages/django/views/generic/base.py", line 104, in view
    return self.dispatch(request, *args, **kwargs)
           ^^^^^^^^^^^^^^^^^^^^^^^^^^^^^^^^^^^^^^^
  File "/Users/moskvinangarkhaev/PycharmProjects/python_django/venv/lib/python3.11/site-packages/django/contrib/auth/mixins.py", line 135, in dispatch
    return super().dispatch(request, *args, **kwargs)
           ^^^^^^^^^^^^^^^^^^^^^^^^^^^^^^^^^^^^^^^^^^
  File "/Users/moskvinangarkhaev/PycharmProjects/python_django/venv/lib/python3.11/site-packages/django/views/generic/base.py", line 143, in dispatch
    return handler(request, *args, **kwargs)
           ^^^^^^^^^^^^^^^^^^^^^^^^^^^^^^^^^
  File "/Users/moskvinangarkhaev/PycharmProjects/python_django/venv/lib/python3.11/site-packages/django/views/generic/edit.py", line 258, in post
    return self.form_valid(form)
           ^^^^^^^^^^^^^^^^^^^^^
  File "/Users/moskvinangarkhaev/PycharmProjects/python_django/venv/lib/python3.11/site-packages/django/views/generic/edit.py", line 263, in form_valid
    success_url = self.get_success_url()
                  ^^^^^^^^^^^^^^^^^^^^^^
  File "/Users/moskvinangarkhaev/PycharmProjects/python_django/mysite/shopapp/views.py", line 254, in get_success_url
    return reverse("shopapp:user_orders_list", kwargs={"pk": self.object.user.pk})
           ^^^^^^^^^^^^^^^^^^^^^^^^^^^^^^^^^^^^^^^^^^^^^^^^^^^^^^^^^^^^^^^^^^^^^^^
  File "/Users/moskvinangarkhaev/PycharmProjects/python_django/venv/lib/python3.11/site-packages/django/urls/base.py", line 88, in reverse
    return resolver._reverse_with_prefix(view, prefix, *args, **kwargs)
           ^^^^^^^^^^^^^^^^^^^^^^^^^^^^^^^^^^^^^^^^^^^^^^^^^^^^^^^^^^^^
  File "/Users/moskvinangarkhaev/PycharmProjects/python_django/venv/lib/python3.11/site-packages/django/urls/resolvers.py", line 851, in _reverse_with_prefix
    raise NoReverseMatch(msg)
django.urls.exceptions.NoReverseMatch: Reverse for 'user_orders_list' with keyword arguments '{'pk': 7}' not found. 1 pattern(s) tried: ['ru/shop/users/(?P<user_id>[0-9]+)/orders/\\Z']
2024-07-22 18:40:37,529 | INFO | django.utils.autoreload | /Users/moskvinangarkhaev/PycharmProjects/python_django/mysite/shopapp/views.py changed, reloading.
2024-07-22 18:40:37,983 | INFO | django.utils.autoreload | Watching for file changes with StatReloader
2024-07-22 18:42:08,508 | WARNING | django.request | Forbidden (Permission denied): /ru/shop/users/1/orders/
Traceback (most recent call last):
  File "/Users/moskvinangarkhaev/PycharmProjects/python_django/venv/lib/python3.11/site-packages/django/core/handlers/exception.py", line 55, in inner
    response = get_response(request)
               ^^^^^^^^^^^^^^^^^^^^^
  File "/Users/moskvinangarkhaev/PycharmProjects/python_django/venv/lib/python3.11/site-packages/django/core/handlers/base.py", line 197, in _get_response
    response = wrapped_callback(request, *callback_args, **callback_kwargs)
               ^^^^^^^^^^^^^^^^^^^^^^^^^^^^^^^^^^^^^^^^^^^^^^^^^^^^^^^^^^^^
  File "/Users/moskvinangarkhaev/PycharmProjects/python_django/venv/lib/python3.11/site-packages/django/views/generic/base.py", line 104, in view
    return self.dispatch(request, *args, **kwargs)
           ^^^^^^^^^^^^^^^^^^^^^^^^^^^^^^^^^^^^^^^
  File "/Users/moskvinangarkhaev/PycharmProjects/python_django/venv/lib/python3.11/site-packages/django/contrib/auth/mixins.py", line 134, in dispatch
    return self.handle_no_permission()
           ^^^^^^^^^^^^^^^^^^^^^^^^^^^
  File "/Users/moskvinangarkhaev/PycharmProjects/python_django/venv/lib/python3.11/site-packages/django/contrib/auth/mixins.py", line 48, in handle_no_permission
    raise PermissionDenied(self.get_permission_denied_message())
django.core.exceptions.PermissionDenied
2024-07-23 06:52:06,625 | INFO | django.utils.autoreload | /Users/moskvinangarkhaev/PycharmProjects/python_django/mysite/shopapp/views.py changed, reloading.
2024-07-23 06:52:07,135 | INFO | django.utils.autoreload | Watching for file changes with StatReloader
2024-07-23 06:52:20,551 | WARNING | django.request | Forbidden (Permission denied): /ru/shop/orders/
Traceback (most recent call last):
  File "/Users/moskvinangarkhaev/PycharmProjects/python_django/venv/lib/python3.11/site-packages/django/core/handlers/exception.py", line 55, in inner
    response = get_response(request)
               ^^^^^^^^^^^^^^^^^^^^^
  File "/Users/moskvinangarkhaev/PycharmProjects/python_django/venv/lib/python3.11/site-packages/django/core/handlers/base.py", line 197, in _get_response
    response = wrapped_callback(request, *callback_args, **callback_kwargs)
               ^^^^^^^^^^^^^^^^^^^^^^^^^^^^^^^^^^^^^^^^^^^^^^^^^^^^^^^^^^^^
  File "/Users/moskvinangarkhaev/PycharmProjects/python_django/venv/lib/python3.11/site-packages/django/views/generic/base.py", line 104, in view
    return self.dispatch(request, *args, **kwargs)
           ^^^^^^^^^^^^^^^^^^^^^^^^^^^^^^^^^^^^^^^
  File "/Users/moskvinangarkhaev/PycharmProjects/python_django/venv/lib/python3.11/site-packages/django/contrib/auth/mixins.py", line 108, in dispatch
    return self.handle_no_permission()
           ^^^^^^^^^^^^^^^^^^^^^^^^^^^
  File "/Users/moskvinangarkhaev/PycharmProjects/python_django/venv/lib/python3.11/site-packages/django/contrib/auth/mixins.py", line 48, in handle_no_permission
    raise PermissionDenied(self.get_permission_denied_message())
django.core.exceptions.PermissionDenied
2024-07-23 06:52:32,762 | WARNING | django.request | Not Found: /ru/myauth/about-me/1
2024-07-23 07:03:01,392 | INFO | django.utils.autoreload | /Users/moskvinangarkhaev/PycharmProjects/python_django/mysite/shopapp/views.py changed, reloading.
2024-07-23 07:03:01,855 | INFO | django.utils.autoreload | Watching for file changes with StatReloader
2024-07-23 07:04:06,261 | INFO | django.utils.autoreload | /Users/moskvinangarkhaev/PycharmProjects/python_django/mysite/shopapp/views.py changed, reloading.
2024-07-23 07:04:06,695 | INFO | django.utils.autoreload | Watching for file changes with StatReloader
2024-07-23 07:04:46,472 | INFO | django.utils.autoreload | /Users/moskvinangarkhaev/PycharmProjects/python_django/mysite/shopapp/views.py changed, reloading.
2024-07-23 07:04:46,890 | INFO | django.utils.autoreload | Watching for file changes with StatReloader
2024-07-23 07:05:14,115 | INFO | django.utils.autoreload | /Users/moskvinangarkhaev/PycharmProjects/python_django/mysite/shopapp/views.py changed, reloading.
2024-07-23 07:05:14,637 | INFO | django.utils.autoreload | Watching for file changes with StatReloader
2024-07-23 07:09:14,173 | INFO | django.utils.autoreload | /Users/moskvinangarkhaev/PycharmProjects/python_django/mysite/shopapp/views.py changed, reloading.
2024-07-23 07:09:14,612 | INFO | django.utils.autoreload | Watching for file changes with StatReloader
2024-07-23 07:10:08,772 | INFO | django.utils.autoreload | /Users/moskvinangarkhaev/PycharmProjects/python_django/mysite/shopapp/views.py changed, reloading.
2024-07-23 07:10:09,205 | INFO | django.utils.autoreload | Watching for file changes with StatReloader
2024-07-23 07:10:16,037 | ERROR | django.request | Internal Server Error: /ru/shop/users/7/order/export
Traceback (most recent call last):
  File "/Users/moskvinangarkhaev/PycharmProjects/python_django/venv/lib/python3.11/site-packages/django/core/handlers/exception.py", line 55, in inner
    response = get_response(request)
               ^^^^^^^^^^^^^^^^^^^^^
  File "/Users/moskvinangarkhaev/PycharmProjects/python_django/venv/lib/python3.11/site-packages/django/core/handlers/base.py", line 197, in _get_response
    response = wrapped_callback(request, *callback_args, **callback_kwargs)
               ^^^^^^^^^^^^^^^^^^^^^^^^^^^^^^^^^^^^^^^^^^^^^^^^^^^^^^^^^^^^
  File "/Users/moskvinangarkhaev/PycharmProjects/python_django/venv/lib/python3.11/site-packages/django/views/generic/base.py", line 104, in view
    return self.dispatch(request, *args, **kwargs)
           ^^^^^^^^^^^^^^^^^^^^^^^^^^^^^^^^^^^^^^^
  File "/Users/moskvinangarkhaev/PycharmProjects/python_django/venv/lib/python3.11/site-packages/django/contrib/auth/mixins.py", line 135, in dispatch
    return super().dispatch(request, *args, **kwargs)
           ^^^^^^^^^^^^^^^^^^^^^^^^^^^^^^^^^^^^^^^^^^
  File "/Users/moskvinangarkhaev/PycharmProjects/python_django/venv/lib/python3.11/site-packages/django/views/generic/base.py", line 143, in dispatch
    return handler(request, *args, **kwargs)
           ^^^^^^^^^^^^^^^^^^^^^^^^^^^^^^^^^
TypeError: UserOrderExportJson.get() got an unexpected keyword argument 'user_id'
2024-07-23 07:12:47,385 | ERROR | django.request | Internal Server Error: /ru/shop/users/7/order/export
Traceback (most recent call last):
  File "/Users/moskvinangarkhaev/PycharmProjects/python_django/venv/lib/python3.11/site-packages/django/core/handlers/exception.py", line 55, in inner
    response = get_response(request)
               ^^^^^^^^^^^^^^^^^^^^^
  File "/Users/moskvinangarkhaev/PycharmProjects/python_django/venv/lib/python3.11/site-packages/django/core/handlers/base.py", line 197, in _get_response
    response = wrapped_callback(request, *callback_args, **callback_kwargs)
               ^^^^^^^^^^^^^^^^^^^^^^^^^^^^^^^^^^^^^^^^^^^^^^^^^^^^^^^^^^^^
  File "/Users/moskvinangarkhaev/PycharmProjects/python_django/venv/lib/python3.11/site-packages/django/views/generic/base.py", line 104, in view
    return self.dispatch(request, *args, **kwargs)
           ^^^^^^^^^^^^^^^^^^^^^^^^^^^^^^^^^^^^^^^
  File "/Users/moskvinangarkhaev/PycharmProjects/python_django/venv/lib/python3.11/site-packages/django/contrib/auth/mixins.py", line 135, in dispatch
    return super().dispatch(request, *args, **kwargs)
           ^^^^^^^^^^^^^^^^^^^^^^^^^^^^^^^^^^^^^^^^^^
  File "/Users/moskvinangarkhaev/PycharmProjects/python_django/venv/lib/python3.11/site-packages/django/views/generic/base.py", line 143, in dispatch
    return handler(request, *args, **kwargs)
           ^^^^^^^^^^^^^^^^^^^^^^^^^^^^^^^^^
TypeError: UserOrderExportJson.get() got an unexpected keyword argument 'user_id'
2024-07-23 07:19:33,928 | INFO | django.utils.autoreload | /Users/moskvinangarkhaev/PycharmProjects/python_django/mysite/shopapp/views.py changed, reloading.
2024-07-23 07:19:34,367 | INFO | django.utils.autoreload | Watching for file changes with StatReloader
2024-07-23 07:21:21,438 | INFO | django.utils.autoreload | /Users/moskvinangarkhaev/PycharmProjects/python_django/mysite/shopapp/views.py changed, reloading.
2024-07-23 07:21:22,062 | INFO | django.utils.autoreload | Watching for file changes with StatReloader
2024-07-23 07:23:51,144 | INFO | django.utils.autoreload | /Users/moskvinangarkhaev/PycharmProjects/python_django/mysite/shopapp/views.py changed, reloading.
2024-07-23 07:23:51,582 | INFO | django.utils.autoreload | Watching for file changes with StatReloader
2024-07-23 07:27:33,502 | INFO | django.utils.autoreload | /Users/moskvinangarkhaev/PycharmProjects/python_django/mysite/shopapp/views.py changed, reloading.
2024-07-23 07:27:33,883 | INFO | django.utils.autoreload | Watching for file changes with StatReloader
2024-07-23 07:35:29,816 | INFO | django.utils.autoreload | /Users/moskvinangarkhaev/PycharmProjects/python_django/mysite/shopapp/views.py changed, reloading.
2024-07-23 07:35:30,547 | INFO | django.utils.autoreload | Watching for file changes with StatReloader
2024-07-23 07:35:56,583 | INFO | django.utils.autoreload | /Users/moskvinangarkhaev/PycharmProjects/python_django/mysite/shopapp/views.py changed, reloading.
2024-07-23 07:35:56,954 | INFO | django.utils.autoreload | Watching for file changes with StatReloader
2024-07-23 07:40:13,107 | WARNING | django.request | Not Found: /ru/shop/order/10/delete
2024-07-23 07:44:09,375 | INFO | django.utils.autoreload | /Users/moskvinangarkhaev/PycharmProjects/python_django/mysite/shopapp/views.py changed, reloading.
2024-07-23 07:46:42,697 | INFO | django.utils.autoreload | Watching for file changes with StatReloader
